Workbook

Sheet Data
A1: Week # | B1: Date | C1: Opponent | D1: Player | E1: 01 Points | F1: 01 Darts | G1: 3DA | H1: PPD | I1: Cricket Marks | J1: Cricket Darts | K1: MPR | L1: DO Hits | M1: DO Opps | N1: DO% | O1: Games W | P1: Games L
A2: 1 | B2: 46282 | C2: 4-Curran's Irish Inn (Dina) | D2: Mike Broderick | E2: 668 | F2: 38 | G2: =IF(N(F2)>0,E2/F2*3,"") | H2: =IF(N(F2)>0,E2/F2,"") | I2: 6 | J2: 21 | K2: =IF(N(J2)>0,I2/J2*3,"") | L2: 1 | M2: 4 | N2: =IF(N(M2)>0,L2/M2,"") | O2: 2 | P2: 2
A3: 1 | B3: 46282 | C3: 4-Curran's Irish Inn (Dina) | D3: Jeff Broderick | E3: 1269 | F3: 82 | G3: =IF(N(F3)>0,E3/F3*3,"") | H3: =IF(N(F3)>0,E3/F3,"") | I3: 14 | J3: 17 | K3: =IF(N(J3)>0,I3/J3*3,"") | L3: 2 | M3: 6 | N3: =IF(N(M3)>0,L3/M3,"") | O3: 5 | P3: 2
A4: 1 | B4: 46282 | C4: 4-Curran's Irish Inn (Dina) | D4: Captain (Vince Clemins) | E4: 1193 | F4: 86 | G4: =IF(N(F4)>0,E4/F4*3,"") | H4: =IF(N(F4)>0,E4/F4,"") | I4: 17 | J4: 18 | K4: =IF(N(J4)>0,I4/J4*3,"") | L4: 1 | M4: 9 | N4: =IF(N(M4)>0,L4/M4,"") | O4: 4 | P4: 3
A5: 1 | B5: 46282 | C5: 4-Curran's Irish Inn (Dina) | D5: Al Fromenko | E5: 1233 | F5: 87 | G5: =IF(N(F5)>0,E5/F5*3,"") | H5: =IF(N(F5)>0,E5/F5,"") | I5: 16 | J5: 20 | K5: =IF(N(J5)>0,I5/J5*3,"") | L5: 1 | M5: 9 | N5: =IF(N(M5)>0,L5/M5,"") | O5: 5 | P5: 2
A6: 1 | B6: 46282 | C6: 4-Curran's Irish Inn (Dina) | D6: Bill Prelle | E6: 488 | F6: 39 | G6: =IF(N(F6)>0,E6/F6*3,"") | H6: =IF(N(F6)>0,E6/F6,"") | K6: =IF(N(J6)>0,I6/J6*3,"") | L6: 0 | M6: 4 | N6: =IF(N(M6)>0,L6/M6,"") | O6: 1 | P6: 2
A7: 1 | B7: 46282 | C7: 4-Curran's Irish Inn (Dina) | D7: Keith McCarthy | E7: 247 | F7: 23 | G7: =IF(N(F7)>0,E7/F7*3,"") | H7: =IF(N(F7)>0,E7/F7,"") | K7: =IF(N(J7)>0,I7/J7*3,"") | L7: 1 | M7: 3 | N7: =IF(N(M7)>0,L7/M7,"") | O7: 2 | P7: 0
A8: 1 | B8: 46282 | C8: 4-Curran's Irish Inn (Dina) | D8: Tom Davis | E8: 609 | F8: 47 | G8: =IF(N(F8)>0,E8/F8*3,"") | H8: =IF(N(F8)>0,E8/F8,"") | I8: 12 | J8: 18 | K8: =IF(N(J8)>0,I8/J8*3,"") | L8: 1 | M8: 6 | N8: =IF(N(M8)>0,L8/M8,"") | O8: 2 | P8: 3
A9: 1 | B9: 46282 | C9: 4-Curran's Irish Inn (Dina) | D9: John Klemick | E9: 1263 | F9: 75 | G9: =IF(N(F9)>0,E9/F9*3,"") | H9: =IF(N(F9)>0,E9/F9,"") | I9: 11 | J9: 15 | K9: =IF(N(J9)>0,I9/J9*3,"") | L9: 0 | M9: 7 | N9: =IF(N(M9)>0,L9/M9,"") | O9: 4 | P9: 3
A10: 1 | B10: 46282 | C10: 4-Curran's Irish Inn (Dina) | D10: Frank Gillespie | G10: =IF(N(F10)>0,E10/F10*3,"") | H10: =IF(N(F10)>0,E10/F10,"") | K10: =IF(N(J10)>0,I10/J10*3,"") | N10: =IF(N(M10)>0,L10/M10,"")
A11: 1 | B11: 46282 | C11: 4-Curran's Irish Inn (Dina) | D11: Jim Wright | G11: =IF(N(F11)>0,E11/F11*3,"") | H11: =IF(N(F11)>0,E11/F11,"") | K11: =IF(N(J11)>0,I11/J11*3,"") | N11: =IF(N(M11)>0,L11/M11,"")
A12: 1 | B12: 46282 | C12: 4-Curran's Irish Inn (Dina) | D12: Dave Keppler | G12: =IF(N(F12)>0,E12/F12*3,"") | H12: =IF(N(F12)>0,E12/F12,"") | K12: =IF(N(J12)>0,I12/J12*3,"") | N12: =IF(N(M12)>0,L12/M12,"")
A13: 2 | B13: 46289 | C13: 2-Polonia (Baisch) | D13: Mike Broderick | E13: 686 | F13: 45 | G13: =IF(N(F13)>0,E13/F13*3,"") | H13: =IF(N(F13)>0,E13/F13,"") | I13: 10 | J13: 18 | K13: =IF(N(J13)>0,I13/J13*3,"") | L13: 0 | M13: 5 | N13: =IF(N(M13)>0,L13/M13,"") | O13: 3 | P13: 1
A14: 2 | B14: 46289 | C14: 2-Polonia (Baisch) | D14: Jeff Broderick | E14: 1103 | F14: 70 | G14: =IF(N(F14)>0,E14/F14*3,"") | H14: =IF(N(F14)>0,E14/F14,"") | I14: 14 | J14: 27 | K14: =IF(N(J14)>0,I14/J14*3,"") | L14: 1 | M14: 9 | N14: =IF(N(M14)>0,L14/M14,"") | O14: 3 | P14: 3
A15: 2 | B15: 46289 | C15: 2-Polonia (Baisch) | D15: Captain (Vince Clemins) | E15: 1027 | F15: 84 | G15: =IF(N(F15)>0,E15/F15*3,"") | H15: =IF(N(F15)>0,E15/F15,"") | I15: 13 | J15: 27 | K15: =IF(N(J15)>0,I15/J15*3,"") | L15: 1 | M15: 13 | N15: =IF(N(M15)>0,L15/M15,"") | O15: 3 | P15: 3
A16: 2 | B16: 46289 | C16: 2-Polonia (Baisch) | D16: Al Fromenko | E16: 1086 | F16: 83 | G16: =IF(N(F16)>0,E16/F16*3,"") | H16: =IF(N(F16)>0,E16/F16,"") | I16: 18 | J16: 19 | K16: =IF(N(J16)>0,I16/J16*3,"") | L16: 1 | M16: 10 | N16: =IF(N(M16)>0,L16/M16,"") | O16: 5 | P16: 2
A17: 2 | B17: 46289 | C17: 2-Polonia (Baisch) | D17: Bill Prelle | E17: 399 | F17: 34 | G17: =IF(N(F17)>0,E17/F17*3,"") | H17: =IF(N(F17)>0,E17/F17,"") | K17: =IF(N(J17)>0,I17/J17*3,"") | L17: 2 | M17: 6 | N17: =IF(N(M17)>0,L17/M17,"") | O17: 2 | P17: 0
A18: 2 | B18: 46289 | C18: 2-Polonia (Baisch) | D18: Keith McCarthy | E18: 93 | F18: 9 | G18: =IF(N(F18)>0,E18/F18*3,"") | H18: =IF(N(F18)>0,E18/F18,"") | K18: =IF(N(J18)>0,I18/J18*3,"") | N18: =IF(N(M18)>0,L18/M18,"") | O18: 0 | P18: 1
A19: 2 | B19: 46289 | C19: 2-Polonia (Baisch) | D19: Tom Davis | E19: 343 | F19: 33 | G19: =IF(N(F19)>0,E19/F19*3,"") | H19: =IF(N(F19)>0,E19/F19,"") | K19: =IF(N(J19)>0,I19/J19*3,"") | L19: 0 | M19: 6 | N19: =IF(N(M19)>0,L19/M19,"") | O19: 2 | P19: 1
A20: 2 | B20: 46289 | C20: 2-Polonia (Baisch) | D20: John Klemick | G20: =IF(N(F20)>0,E20/F20*3,"") | H20: =IF(N(F20)>0,E20/F20,"") | K20: =IF(N(J20)>0,I20/J20*3,"") | N20: =IF(N(M20)>0,L20/M20,"")
A21: 2 | B21: 46289 | C21: 2-Polonia (Baisch) | D21: Frank Gillespie | E21: 331 | F21: 25 | G21: =IF(N(F21)>0,E21/F21*3,"") | H21: =IF(N(F21)>0,E21/F21,"") | K21: =IF(N(J21)>0,I21/J21*3,"") | L21: 1 | M21: 4 | N21: =IF(N(M21)>0,L21/M21,"") | O21: 2 | P21: 0
A22: 2 | B22: 46289 | C22: 2-Polonia (Baisch) | D22: Jim Wright | E22: 628 | F22: 42 | G22: =IF(N(F22)>0,E22/F22*3,"") | H22: =IF(N(F22)>0,E22/F22,"") | I22: 14 | J22: 26 | K22: =IF(N(J22)>0,I22/J22*3,"") | L22: 0 | M22: 4 | N22: =IF(N(M22)>0,L22/M22,"") | O22: 3 | P22: 1
A23: 2 | B23: 46289 | C23: 2-Polonia (Baisch) | D23: Dave Keppler | E23: 1390 | F23: 87 | G23: =IF(N(F23)>0,E23/F23*3,"") | H23: =IF(N(F23)>0,E23/F23,"") | I23: 29 | J23: 27 | K23: =IF(N(J23)>0,I23/J23*3,"") | L23: 2 | M23: 10 | N23: =IF(N(M23)>0,L23/M23,"") | O23: 5 | P23: 2

Sheet 3DA by Week
A1: Player | B1: W1 (9/17) | C1: W2 (9/24) | D1: W3 (10/1) | E1: W4 (10/8) | F1: W5 (10/15) | G1: W6 (10/22) | H1: W7 (10/29) | I1: W8 (11/5) | J1: W9 (11/12) | K1: W10 (11/19) | L1: Season 3DA | M1: Best Week | N1: Worst Week | O1: Weeks Played | P1: Latest | Q1: Best Wk | S1: Sort Key (helper)
A2: Week # | B2: 1 | C2: 2 | D2: 3 | E2: 4 | F2: 5 | G2: 6 | H2: 7 | I2: 8 | J2: 9 | K2: 10
A3: Mike Broderick | B3: =IFERROR(SUMIFS(Data!$E:$E,Data!$A:$A,B$2,Data!$D:$D,$A3)/SUMIFS(Data!$F:$F,Data!$A:$A,B$2,Data!$D:$D,$A3)*3,"") | C3: =IFERROR(SUMIFS(Data!$E:$E,Data!$A:$A,C$2,Data!$D:$D,$A3)/SUMIFS(Data!$F:$F,Data!$A:$A,C$2,Data!$D:$D,$A3)*3,"") | D3: =IFERROR(SUMIFS(Data!$E:$E,Data!$A:$A,D$2,Data!$D:$D,$A3)/SUMIFS(Data!$F:$F,Data!$A:$A,D$2,Data!$D:$D,$A3)*3,"") | E3: =IFERROR(SUMIFS(Data!$E:$E,Data!$A:$A,E$2,Data!$D:$D,$A3)/SUMIFS(Data!$F:$F,Data!$A:$A,E$2,Data!$D:$D,$A3)*3,"") | F3: =IFERROR(SUMIFS(Data!$E:$E,Data!$A:$A,F$2,Data!$D:$D,$A3)/SUMIFS(Data!$F:$F,Data!$A:$A,F$2,Data!$D:$D,$A3)*3,"") | G3: =IFERROR(SUMIFS(Data!$E:$E,Data!$A:$A,G$2,Data!$D:$D,$A3)/SUMIFS(Data!$F:$F,Data!$A:$A,G$2,Data!$D:$D,$A3)*3,"") | H3: =IFERROR(SUMIFS(Data!$E:$E,Data!$A:$A,H$2,Data!$D:$D,$A3)/SUMIFS(Data!$F:$F,Data!$A:$A,H$2,Data!$D:$D,$A3)*3,"") | I3: =IFERROR(SUMIFS(Data!$E:$E,Data!$A:$A,I$2,Data!$D:$D,$A3)/SUMIFS(Data!$F:$F,Data!$A:$A,I$2,Data!$D:$D,$A3)*3,"") | ... K3: =IFERROR(SUMIFS(Data!$E:$E,Data!$A:$A,K$2,Data!$D:$D,$A3)/SUMIFS(Data!$F:$F,Data!$A:$A,K$2,Data!$D:$D,$A3)*3,"") | L3: =IFERROR(SUMIFS(Data!$E:$E,Data!$D:$D,$A3)/SUMIFS(Data!$F:$F,Data!$D:$D,$A3)*3,"") | M3: =IF(COUNT(B3:K3)=0,"",MAX(B3:K3)) | N3: =IF(COUNT(B3:K3)=0,"",MIN(B3:K3)) | O3: =COUNT(B3:K3) | P3: =IF(COUNT(B3:K3)=0,"",INDEX(B3:K3,_xlfn.MAXIFS($B$2:$K$2,B3:K3,">=0"))) | Q3: =IF(COUNT(B3:K3)=0,"","W"&INDEX($B$2:$K$2,MATCH(M3,B3:K3,0))) | S3: =IF(ISNUMBER(L3),L3,-1)-ROW()/1000000
A4: Jeff Broderick | B4: =IFERROR(SUMIFS(Data!$E:$E,Data!$A:$A,B$2,Data!$D:$D,$A4)/SUMIFS(Data!$F:$F,Data!$A:$A,B$2,Data!$D:$D,$A4)*3,"") | C4: =IFERROR(SUMIFS(Data!$E:$E,Data!$A:$A,C$2,Data!$D:$D,$A4)/SUMIFS(Data!$F:$F,Data!$A:$A,C$2,Data!$D:$D,$A4)*3,"") | D4: =IFERROR(SUMIFS(Data!$E:$E,Data!$A:$A,D$2,Data!$D:$D,$A4)/SUMIFS(Data!$F:$F,Data!$A:$A,D$2,Data!$D:$D,$A4)*3,"") | E4: =IFERROR(SUMIFS(Data!$E:$E,Data!$A:$A,E$2,Data!$D:$D,$A4)/SUMIFS(Data!$F:$F,Data!$A:$A,E$2,Data!$D:$D,$A4)*3,"") | F4: =IFERROR(SUMIFS(Data!$E:$E,Data!$A:$A,F$2,Data!$D:$D,$A4)/SUMIFS(Data!$F:$F,Data!$A:$A,F$2,Data!$D:$D,$A4)*3,"") | G4: =IFERROR(SUMIFS(Data!$E:$E,Data!$A:$A,G$2,Data!$D:$D,$A4)/SUMIFS(Data!$F:$F,Data!$A:$A,G$2,Data!$D:$D,$A4)*3,"") | H4: =IFERROR(SUMIFS(Data!$E:$E,Data!$A:$A,H$2,Data!$D:$D,$A4)/SUMIFS(Data!$F:$F,Data!$A:$A,H$2,Data!$D:$D,$A4)*3,"") | I4: =IFERROR(SUMIFS(Data!$E:$E,Data!$A:$A,I$2,Data!$D:$D,$A4)/SUMIFS(Data!$F:$F,Data!$A:$A,I$2,Data!$D:$D,$A4)*3,"") | ... K4: =IFERROR(SUMIFS(Data!$E:$E,Data!$A:$A,K$2,Data!$D:$D,$A4)/SUMIFS(Data!$F:$F,Data!$A:$A,K$2,Data!$D:$D,$A4)*3,"") | L4: =IFERROR(SUMIFS(Data!$E:$E,Data!$D:$D,$A4)/SUMIFS(Data!$F:$F,Data!$D:$D,$A4)*3,"") | M4: =IF(COUNT(B4:K4)=0,"",MAX(B4:K4)) | N4: =IF(COUNT(B4:K4)=0,"",MIN(B4:K4)) | O4: =COUNT(B4:K4) | P4: =IF(COUNT(B4:K4)=0,"",INDEX(B4:K4,_xlfn.MAXIFS($B$2:$K$2,B4:K4,">=0"))) | Q4: =IF(COUNT(B4:K4)=0,"","W"&INDEX($B$2:$K$2,MATCH(M4,B4:K4,0))) | S4: =IF(ISNUMBER(L4),L4,-1)-ROW()/1000000
A5: Captain (Vince Clemins) | B5: =IFERROR(SUMIFS(Data!$E:$E,Data!$A:$A,B$2,Data!$D:$D,$A5)/SUMIFS(Data!$F:$F,Data!$A:$A,B$2,Data!$D:$D,$A5)*3,"") | C5: =IFERROR(SUMIFS(Data!$E:$E,Data!$A:$A,C$2,Data!$D:$D,$A5)/SUMIFS(Data!$F:$F,Data!$A:$A,C$2,Data!$D:$D,$A5)*3,"") | D5: =IFERROR(SUMIFS(Data!$E:$E,Data!$A:$A,D$2,Data!$D:$D,$A5)/SUMIFS(Data!$F:$F,Data!$A:$A,D$2,Data!$D:$D,$A5)*3,"") | E5: =IFERROR(SUMIFS(Data!$E:$E,Data!$A:$A,E$2,Data!$D:$D,$A5)/SUMIFS(Data!$F:$F,Data!$A:$A,E$2,Data!$D:$D,$A5)*3,"") | F5: =IFERROR(SUMIFS(Data!$E:$E,Data!$A:$A,F$2,Data!$D:$D,$A5)/SUMIFS(Data!$F:$F,Data!$A:$A,F$2,Data!$D:$D,$A5)*3,"") | G5: =IFERROR(SUMIFS(Data!$E:$E,Data!$A:$A,G$2,Data!$D:$D,$A5)/SUMIFS(Data!$F:$F,Data!$A:$A,G$2,Data!$D:$D,$A5)*3,"") | H5: =IFERROR(SUMIFS(Data!$E:$E,Data!$A:$A,H$2,Data!$D:$D,$A5)/SUMIFS(Data!$F:$F,Data!$A:$A,H$2,Data!$D:$D,$A5)*3,"") | I5: =IFERROR(SUMIFS(Data!$E:$E,Data!$A:$A,I$2,Data!$D:$D,$A5)/SUMIFS(Data!$F:$F,Data!$A:$A,I$2,Data!$D:$D,$A5)*3,"") | ... K5: =IFERROR(SUMIFS(Data!$E:$E,Data!$A:$A,K$2,Data!$D:$D,$A5)/SUMIFS(Data!$F:$F,Data!$A:$A,K$2,Data!$D:$D,$A5)*3,"") | L5: =IFERROR(SUMIFS(Data!$E:$E,Data!$D:$D,$A5)/SUMIFS(Data!$F:$F,Data!$D:$D,$A5)*3,"") | M5: =IF(COUNT(B5:K5)=0,"",MAX(B5:K5)) | N5: =IF(COUNT(B5:K5)=0,"",MIN(B5:K5)) | O5: =COUNT(B5:K5) | P5: =IF(COUNT(B5:K5)=0,"",INDEX(B5:K5,_xlfn.MAXIFS($B$2:$K$2,B5:K5,">=0"))) | Q5: =IF(COUNT(B5:K5)=0,"","W"&INDEX($B$2:$K$2,MATCH(M5,B5:K5,0))) | S5: =IF(ISNUMBER(L5),L5,-1)-ROW()/1000000
A6: Al Fromenko | B6: =IFERROR(SUMIFS(Data!$E:$E,Data!$A:$A,B$2,Data!$D:$D,$A6)/SUMIFS(Data!$F:$F,Data!$A:$A,B$2,Data!$D:$D,$A6)*3,"") | C6: =IFERROR(SUMIFS(Data!$E:$E,Data!$A:$A,C$2,Data!$D:$D,$A6)/SUMIFS(Data!$F:$F,Data!$A:$A,C$2,Data!$D:$D,$A6)*3,"") | D6: =IFERROR(SUMIFS(Data!$E:$E,Data!$A:$A,D$2,Data!$D:$D,$A6)/SUMIFS(Data!$F:$F,Data!$A:$A,D$2,Data!$D:$D,$A6)*3,"") | E6: =IFERROR(SUMIFS(Data!$E:$E,Data!$A:$A,E$2,Data!$D:$D,$A6)/SUMIFS(Data!$F:$F,Data!$A:$A,E$2,Data!$D:$D,$A6)*3,"") | F6: =IFERROR(SUMIFS(Data!$E:$E,Data!$A:$A,F$2,Data!$D:$D,$A6)/SUMIFS(Data!$F:$F,Data!$A:$A,F$2,Data!$D:$D,$A6)*3,"") | G6: =IFERROR(SUMIFS(Data!$E:$E,Data!$A:$A,G$2,Data!$D:$D,$A6)/SUMIFS(Data!$F:$F,Data!$A:$A,G$2,Data!$D:$D,$A6)*3,"") | H6: =IFERROR(SUMIFS(Data!$E:$E,Data!$A:$A,H$2,Data!$D:$D,$A6)/SUMIFS(Data!$F:$F,Data!$A:$A,H$2,Data!$D:$D,$A6)*3,"") | I6: =IFERROR(SUMIFS(Data!$E:$E,Data!$A:$A,I$2,Data!$D:$D,$A6)/SUMIFS(Data!$F:$F,Data!$A:$A,I$2,Data!$D:$D,$A6)*3,"") | ... K6: =IFERROR(SUMIFS(Data!$E:$E,Data!$A:$A,K$2,Data!$D:$D,$A6)/SUMIFS(Data!$F:$F,Data!$A:$A,K$2,Data!$D:$D,$A6)*3,"") | L6: =IFERROR(SUMIFS(Data!$E:$E,Data!$D:$D,$A6)/SUMIFS(Data!$F:$F,Data!$D:$D,$A6)*3,"") | M6: =IF(COUNT(B6:K6)=0,"",MAX(B6:K6)) | N6: =IF(COUNT(B6:K6)=0,"",MIN(B6:K6)) | O6: =COUNT(B6:K6) | P6: =IF(COUNT(B6:K6)=0,"",INDEX(B6:K6,_xlfn.MAXIFS($B$2:$K$2,B6:K6,">=0"))) | Q6: =IF(COUNT(B6:K6)=0,"","W"&INDEX($B$2:$K$2,MATCH(M6,B6:K6,0))) | S6: =IF(ISNUMBER(L6),L6,-1)-ROW()/1000000
A7: Bill Prelle | B7: =IFERROR(SUMIFS(Data!$E:$E,Data!$A:$A,B$2,Data!$D:$D,$A7)/SUMIFS(Data!$F:$F,Data!$A:$A,B$2,Data!$D:$D,$A7)*3,"") | C7: =IFERROR(SUMIFS(Data!$E:$E,Data!$A:$A,C$2,Data!$D:$D,$A7)/SUMIFS(Data!$F:$F,Data!$A:$A,C$2,Data!$D:$D,$A7)*3,"") | D7: =IFERROR(SUMIFS(Data!$E:$E,Data!$A:$A,D$2,Data!$D:$D,$A7)/SUMIFS(Data!$F:$F,Data!$A:$A,D$2,Data!$D:$D,$A7)*3,"") | E7: =IFERROR(SUMIFS(Data!$E:$E,Data!$A:$A,E$2,Data!$D:$D,$A7)/SUMIFS(Data!$F:$F,Data!$A:$A,E$2,Data!$D:$D,$A7)*3,"") | F7: =IFERROR(SUMIFS(Data!$E:$E,Data!$A:$A,F$2,Data!$D:$D,$A7)/SUMIFS(Data!$F:$F,Data!$A:$A,F$2,Data!$D:$D,$A7)*3,"") | G7: =IFERROR(SUMIFS(Data!$E:$E,Data!$A:$A,G$2,Data!$D:$D,$A7)/SUMIFS(Data!$F:$F,Data!$A:$A,G$2,Data!$D:$D,$A7)*3,"") | H7: =IFERROR(SUMIFS(Data!$E:$E,Data!$A:$A,H$2,Data!$D:$D,$A7)/SUMIFS(Data!$F:$F,Data!$A:$A,H$2,Data!$D:$D,$A7)*3,"") | I7: =IFERROR(SUMIFS(Data!$E:$E,Data!$A:$A,I$2,Data!$D:$D,$A7)/SUMIFS(Data!$F:$F,Data!$A:$A,I$2,Data!$D:$D,$A7)*3,"") | ... K7: =IFERROR(SUMIFS(Data!$E:$E,Data!$A:$A,K$2,Data!$D:$D,$A7)/SUMIFS(Data!$F:$F,Data!$A:$A,K$2,Data!$D:$D,$A7)*3,"") | L7: =IFERROR(SUMIFS(Data!$E:$E,Data!$D:$D,$A7)/SUMIFS(Data!$F:$F,Data!$D:$D,$A7)*3,"") | M7: =IF(COUNT(B7:K7)=0,"",MAX(B7:K7)) | N7: =IF(COUNT(B7:K7)=0,"",MIN(B7:K7)) | O7: =COUNT(B7:K7) | P7: =IF(COUNT(B7:K7)=0,"",INDEX(B7:K7,_xlfn.MAXIFS($B$2:$K$2,B7:K7,">=0"))) | Q7: =IF(COUNT(B7:K7)=0,"","W"&INDEX($B$2:$K$2,MATCH(M7,B7:K7,0))) | S7: =IF(ISNUMBER(L7),L7,-1)-ROW()/1000000
A8: Keith McCarthy | B8: =IFERROR(SUMIFS(Data!$E:$E,Data!$A:$A,B$2,Data!$D:$D,$A8)/SUMIFS(Data!$F:$F,Data!$A:$A,B$2,Data!$D:$D,$A8)*3,"") | C8: =IFERROR(SUMIFS(Data!$E:$E,Data!$A:$A,C$2,Data!$D:$D,$A8)/SUMIFS(Data!$F:$F,Data!$A:$A,C$2,Data!$D:$D,$A8)*3,"") | D8: =IFERROR(SUMIFS(Data!$E:$E,Data!$A:$A,D$2,Data!$D:$D,$A8)/SUMIFS(Data!$F:$F,Data!$A:$A,D$2,Data!$D:$D,$A8)*3,"") | E8: =IFERROR(SUMIFS(Data!$E:$E,Data!$A:$A,E$2,Data!$D:$D,$A8)/SUMIFS(Data!$F:$F,Data!$A:$A,E$2,Data!$D:$D,$A8)*3,"") | F8: =IFERROR(SUMIFS(Data!$E:$E,Data!$A:$A,F$2,Data!$D:$D,$A8)/SUMIFS(Data!$F:$F,Data!$A:$A,F$2,Data!$D:$D,$A8)*3,"") | G8: =IFERROR(SUMIFS(Data!$E:$E,Data!$A:$A,G$2,Data!$D:$D,$A8)/SUMIFS(Data!$F:$F,Data!$A:$A,G$2,Data!$D:$D,$A8)*3,"") | H8: =IFERROR(SUMIFS(Data!$E:$E,Data!$A:$A,H$2,Data!$D:$D,$A8)/SUMIFS(Data!$F:$F,Data!$A:$A,H$2,Data!$D:$D,$A8)*3,"") | I8: =IFERROR(SUMIFS(Data!$E:$E,Data!$A:$A,I$2,Data!$D:$D,$A8)/SUMIFS(Data!$F:$F,Data!$A:$A,I$2,Data!$D:$D,$A8)*3,"") | ... K8: =IFERROR(SUMIFS(Data!$E:$E,Data!$A:$A,K$2,Data!$D:$D,$A8)/SUMIFS(Data!$F:$F,Data!$A:$A,K$2,Data!$D:$D,$A8)*3,"") | L8: =IFERROR(SUMIFS(Data!$E:$E,Data!$D:$D,$A8)/SUMIFS(Data!$F:$F,Data!$D:$D,$A8)*3,"") | M8: =IF(COUNT(B8:K8)=0,"",MAX(B8:K8)) | N8: =IF(COUNT(B8:K8)=0,"",MIN(B8:K8)) | O8: =COUNT(B8:K8) | P8: =IF(COUNT(B8:K8)=0,"",INDEX(B8:K8,_xlfn.MAXIFS($B$2:$K$2,B8:K8,">=0"))) | Q8: =IF(COUNT(B8:K8)=0,"","W"&INDEX($B$2:$K$2,MATCH(M8,B8:K8,0))) | S8: =IF(ISNUMBER(L8),L8,-1)-ROW()/1000000
A9: Tom Davis | B9: =IFERROR(SUMIFS(Data!$E:$E,Data!$A:$A,B$2,Data!$D:$D,$A9)/SUMIFS(Data!$F:$F,Data!$A:$A,B$2,Data!$D:$D,$A9)*3,"") | C9: =IFERROR(SUMIFS(Data!$E:$E,Data!$A:$A,C$2,Data!$D:$D,$A9)/SUMIFS(Data!$F:$F,Data!$A:$A,C$2,Data!$D:$D,$A9)*3,"") | D9: =IFERROR(SUMIFS(Data!$E:$E,Data!$A:$A,D$2,Data!$D:$D,$A9)/SUMIFS(Data!$F:$F,Data!$A:$A,D$2,Data!$D:$D,$A9)*3,"") | E9: =IFERROR(SUMIFS(Data!$E:$E,Data!$A:$A,E$2,Data!$D:$D,$A9)/SUMIFS(Data!$F:$F,Data!$A:$A,E$2,Data!$D:$D,$A9)*3,"") | F9: =IFERROR(SUMIFS(Data!$E:$E,Data!$A:$A,F$2,Data!$D:$D,$A9)/SUMIFS(Data!$F:$F,Data!$A:$A,F$2,Data!$D:$D,$A9)*3,"") | G9: =IFERROR(SUMIFS(Data!$E:$E,Data!$A:$A,G$2,Data!$D:$D,$A9)/SUMIFS(Data!$F:$F,Data!$A:$A,G$2,Data!$D:$D,$A9)*3,"") | H9: =IFERROR(SUMIFS(Data!$E:$E,Data!$A:$A,H$2,Data!$D:$D,$A9)/SUMIFS(Data!$F:$F,Data!$A:$A,H$2,Data!$D:$D,$A9)*3,"") | I9: =IFERROR(SUMIFS(Data!$E:$E,Data!$A:$A,I$2,Data!$D:$D,$A9)/SUMIFS(Data!$F:$F,Data!$A:$A,I$2,Data!$D:$D,$A9)*3,"") | ... K9: =IFERROR(SUMIFS(Data!$E:$E,Data!$A:$A,K$2,Data!$D:$D,$A9)/SUMIFS(Data!$F:$F,Data!$A:$A,K$2,Data!$D:$D,$A9)*3,"") | L9: =IFERROR(SUMIFS(Data!$E:$E,Data!$D:$D,$A9)/SUMIFS(Data!$F:$F,Data!$D:$D,$A9)*3,"") | M9: =IF(COUNT(B9:K9)=0,"",MAX(B9:K9)) | N9: =IF(COUNT(B9:K9)=0,"",MIN(B9:K9)) | O9: =COUNT(B9:K9) | P9: =IF(COUNT(B9:K9)=0,"",INDEX(B9:K9,_xlfn.MAXIFS($B$2:$K$2,B9:K9,">=0"))) | Q9: =IF(COUNT(B9:K9)=0,"","W"&INDEX($B$2:$K$2,MATCH(M9,B9:K9,0))) | S9: =IF(ISNUMBER(L9),L9,-1)-ROW()/1000000
A10: John Klemick | B10: =IFERROR(SUMIFS(Data!$E:$E,Data!$A:$A,B$2,Data!$D:$D,$A10)/SUMIFS(Data!$F:$F,Data!$A:$A,B$2,Data!$D:$D,$A10)*3,"") | C10: =IFERROR(SUMIFS(Data!$E:$E,Data!$A:$A,C$2,Data!$D:$D,$A10)/SUMIFS(Data!$F:$F,Data!$A:$A,C$2,Data!$D:$D,$A10)*3,"") | D10: =IFERROR(SUMIFS(Data!$E:$E,Data!$A:$A,D$2,Data!$D:$D,$A10)/SUMIFS(Data!$F:$F,Data!$A:$A,D$2,Data!$D:$D,$A10)*3,"") | E10: =IFERROR(SUMIFS(Data!$E:$E,Data!$A:$A,E$2,Data!$D:$D,$A10)/SUMIFS(Data!$F:$F,Data!$A:$A,E$2,Data!$D:$D,$A10)*3,"") | F10: =IFERROR(SUMIFS(Data!$E:$E,Data!$A:$A,F$2,Data!$D:$D,$A10)/SUMIFS(Data!$F:$F,Data!$A:$A,F$2,Data!$D:$D,$A10)*3,"") | G10: =IFERROR(SUMIFS(Data!$E:$E,Data!$A:$A,G$2,Data!$D:$D,$A10)/SUMIFS(Data!$F:$F,Data!$A:$A,G$2,Data!$D:$D,$A10)*3,"") | H10: =IFERROR(SUMIFS(Data!$E:$E,Data!$A:$A,H$2,Data!$D:$D,$A10)/SUMIFS(Data!$F:$F,Data!$A:$A,H$2,Data!$D:$D,$A10)*3,"") | I10: =IFERROR(SUMIFS(Data!$E:$E,Data!$A:$A,I$2,Data!$D:$D,$A10)/SUMIFS(Data!$F:$F,Data!$A:$A,I$2,Data!$D:$D,$A10)*3,"") | ... K10: =IFERROR(SUMIFS(Data!$E:$E,Data!$A:$A,K$2,Data!$D:$D,$A10)/SUMIFS(Data!$F:$F,Data!$A:$A,K$2,Data!$D:$D,$A10)*3,"") | L10: =IFERROR(SUMIFS(Data!$E:$E,Data!$D:$D,$A10)/SUMIFS(Data!$F:$F,Data!$D:$D,$A10)*3,"") | M10: =IF(COUNT(B10:K10)=0,"",MAX(B10:K10)) | N10: =IF(COUNT(B10:K10)=0,"",MIN(B10:K10)) | O10: =COUNT(B10:K10) | P10: =IF(COUNT(B10:K10)=0,"",INDEX(B10:K10,_xlfn.MAXIFS($B$2:$K$2,B10:K10,">=0"))) | Q10: =IF(COUNT(B10:K10)=0,"","W"&INDEX($B$2:$K$2,MATCH(M10,B10:K10,0))) | S10: =IF(ISNUMBER(L10),L10,-1)-ROW()/1000000
A11: Frank Gillespie | B11: =IFERROR(SUMIFS(Data!$E:$E,Data!$A:$A,B$2,Data!$D:$D,$A11)/SUMIFS(Data!$F:$F,Data!$A:$A,B$2,Data!$D:$D,$A11)*3,"") | C11: =IFERROR(SUMIFS(Data!$E:$E,Data!$A:$A,C$2,Data!$D:$D,$A11)/SUMIFS(Data!$F:$F,Data!$A:$A,C$2,Data!$D:$D,$A11)*3,"") | D11: =IFERROR(SUMIFS(Data!$E:$E,Data!$A:$A,D$2,Data!$D:$D,$A11)/SUMIFS(Data!$F:$F,Data!$A:$A,D$2,Data!$D:$D,$A11)*3,"") | E11: =IFERROR(SUMIFS(Data!$E:$E,Data!$A:$A,E$2,Data!$D:$D,$A11)/SUMIFS(Data!$F:$F,Data!$A:$A,E$2,Data!$D:$D,$A11)*3,"") | F11: =IFERROR(SUMIFS(Data!$E:$E,Data!$A:$A,F$2,Data!$D:$D,$A11)/SUMIFS(Data!$F:$F,Data!$A:$A,F$2,Data!$D:$D,$A11)*3,"") | G11: =IFERROR(SUMIFS(Data!$E:$E,Data!$A:$A,G$2,Data!$D:$D,$A11)/SUMIFS(Data!$F:$F,Data!$A:$A,G$2,Data!$D:$D,$A11)*3,"") | H11: =IFERROR(SUMIFS(Data!$E:$E,Data!$A:$A,H$2,Data!$D:$D,$A11)/SUMIFS(Data!$F:$F,Data!$A:$A,H$2,Data!$D:$D,$A11)*3,"") | I11: =IFERROR(SUMIFS(Data!$E:$E,Data!$A:$A,I$2,Data!$D:$D,$A11)/SUMIFS(Data!$F:$F,Data!$A:$A,I$2,Data!$D:$D,$A11)*3,"") | ... K11: =IFERROR(SUMIFS(Data!$E:$E,Data!$A:$A,K$2,Data!$D:$D,$A11)/SUMIFS(Data!$F:$F,Data!$A:$A,K$2,Data!$D:$D,$A11)*3,"") | L11: =IFERROR(SUMIFS(Data!$E:$E,Data!$D:$D,$A11)/SUMIFS(Data!$F:$F,Data!$D:$D,$A11)*3,"") | M11: =IF(COUNT(B11:K11)=0,"",MAX(B11:K11)) | N11: =IF(COUNT(B11:K11)=0,"",MIN(B11:K11)) | O11: =COUNT(B11:K11) | P11: =IF(COUNT(B11:K11)=0,"",INDEX(B11:K11,_xlfn.MAXIFS($B$2:$K$2,B11:K11,">=0"))) | Q11: =IF(COUNT(B11:K11)=0,"","W"&INDEX($B$2:$K$2,MATCH(M11,B11:K11,0))) | S11: =IF(ISNUMBER(L11),L11,-1)-ROW()/1000000
A12: Jim Wright | B12: =IFERROR(SUMIFS(Data!$E:$E,Data!$A:$A,B$2,Data!$D:$D,$A12)/SUMIFS(Data!$F:$F,Data!$A:$A,B$2,Data!$D:$D,$A12)*3,"") | C12: =IFERROR(SUMIFS(Data!$E:$E,Data!$A:$A,C$2,Data!$D:$D,$A12)/SUMIFS(Data!$F:$F,Data!$A:$A,C$2,Data!$D:$D,$A12)*3,"") | D12: =IFERROR(SUMIFS(Data!$E:$E,Data!$A:$A,D$2,Data!$D:$D,$A12)/SUMIFS(Data!$F:$F,Data!$A:$A,D$2,Data!$D:$D,$A12)*3,"") | E12: =IFERROR(SUMIFS(Data!$E:$E,Data!$A:$A,E$2,Data!$D:$D,$A12)/SUMIFS(Data!$F:$F,Data!$A:$A,E$2,Data!$D:$D,$A12)*3,"") | F12: =IFERROR(SUMIFS(Data!$E:$E,Data!$A:$A,F$2,Data!$D:$D,$A12)/SUMIFS(Data!$F:$F,Data!$A:$A,F$2,Data!$D:$D,$A12)*3,"") | G12: =IFERROR(SUMIFS(Data!$E:$E,Data!$A:$A,G$2,Data!$D:$D,$A12)/SUMIFS(Data!$F:$F,Data!$A:$A,G$2,Data!$D:$D,$A12)*3,"") | H12: =IFERROR(SUMIFS(Data!$E:$E,Data!$A:$A,H$2,Data!$D:$D,$A12)/SUMIFS(Data!$F:$F,Data!$A:$A,H$2,Data!$D:$D,$A12)*3,"") | I12: =IFERROR(SUMIFS(Data!$E:$E,Data!$A:$A,I$2,Data!$D:$D,$A12)/SUMIFS(Data!$F:$F,Data!$A:$A,I$2,Data!$D:$D,$A12)*3,"") | ... K12: =IFERROR(SUMIFS(Data!$E:$E,Data!$A:$A,K$2,Data!$D:$D,$A12)/SUMIFS(Data!$F:$F,Data!$A:$A,K$2,Data!$D:$D,$A12)*3,"") | L12: =IFERROR(SUMIFS(Data!$E:$E,Data!$D:$D,$A12)/SUMIFS(Data!$F:$F,Data!$D:$D,$A12)*3,"") | M12: =IF(COUNT(B12:K12)=0,"",MAX(B12:K12)) | N12: =IF(COUNT(B12:K12)=0,"",MIN(B12:K12)) | O12: =COUNT(B12:K12) | P12: =IF(COUNT(B12:K12)=0,"",INDEX(B12:K12,_xlfn.MAXIFS($B$2:$K$2,B12:K12,">=0"))) | Q12: =IF(COUNT(B12:K12)=0,"","W"&INDEX($B$2:$K$2,MATCH(M12,B12:K12,0))) | S12: =IF(ISNUMBER(L12),L12,-1)-ROW()/1000000
A13: Dave Keppler | B13: =IFERROR(SUMIFS(Data!$E:$E,Data!$A:$A,B$2,Data!$D:$D,$A13)/SUMIFS(Data!$F:$F,Data!$A:$A,B$2,Data!$D:$D,$A13)*3,"") | C13: =IFERROR(SUMIFS(Data!$E:$E,Data!$A:$A,C$2,Data!$D:$D,$A13)/SUMIFS(Data!$F:$F,Data!$A:$A,C$2,Data!$D:$D,$A13)*3,"") | D13: =IFERROR(SUMIFS(Data!$E:$E,Data!$A:$A,D$2,Data!$D:$D,$A13)/SUMIFS(Data!$F:$F,Data!$A:$A,D$2,Data!$D:$D,$A13)*3,"") | E13: =IFERROR(SUMIFS(Data!$E:$E,Data!$A:$A,E$2,Data!$D:$D,$A13)/SUMIFS(Data!$F:$F,Data!$A:$A,E$2,Data!$D:$D,$A13)*3,"") | F13: =IFERROR(SUMIFS(Data!$E:$E,Data!$A:$A,F$2,Data!$D:$D,$A13)/SUMIFS(Data!$F:$F,Data!$A:$A,F$2,Data!$D:$D,$A13)*3,"") | G13: =IFERROR(SUMIFS(Data!$E:$E,Data!$A:$A,G$2,Data!$D:$D,$A13)/SUMIFS(Data!$F:$F,Data!$A:$A,G$2,Data!$D:$D,$A13)*3,"") | H13: =IFERROR(SUMIFS(Data!$E:$E,Data!$A:$A,H$2,Data!$D:$D,$A13)/SUMIFS(Data!$F:$F,Data!$A:$A,H$2,Data!$D:$D,$A13)*3,"") | I13: =IFERROR(SUMIFS(Data!$E:$E,Data!$A:$A,I$2,Data!$D:$D,$A13)/SUMIFS(Data!$F:$F,Data!$A:$A,I$2,Data!$D:$D,$A13)*3,"") | ... K13: =IFERROR(SUMIFS(Data!$E:$E,Data!$A:$A,K$2,Data!$D:$D,$A13)/SUMIFS(Data!$F:$F,Data!$A:$A,K$2,Data!$D:$D,$A13)*3,"") | L13: =IFERROR(SUMIFS(Data!$E:$E,Data!$D:$D,$A13)/SUMIFS(Data!$F:$F,Data!$D:$D,$A13)*3,"") | M13: =IF(COUNT(B13:K13)=0,"",MAX(B13:K13)) | N13: =IF(COUNT(B13:K13)=0,"",MIN(B13:K13)) | O13: =COUNT(B13:K13) | P13: =IF(COUNT(B13:K13)=0,"",INDEX(B13:K13,_xlfn.MAXIFS($B$2:$K$2,B13:K13,">=0"))) | Q13: =IF(COUNT(B13:K13)=0,"","W"&INDEX($B$2:$K$2,MATCH(M13,B13:K13,0))) | S13: =IF(ISNUMBER(L13),L13,-1)-ROW()/1000000
A14: TEAM | B14: =IFERROR(SUMIFS(Data!$E:$E,Data!$A:$A,B$2)/SUMIFS(Data!$F:$F,Data!$A:$A,B$2)*3,"") | C14: =IFERROR(SUMIFS(Data!$E:$E,Data!$A:$A,C$2)/SUMIFS(Data!$F:$F,Data!$A:$A,C$2)*3,"") | D14: =IFERROR(SUMIFS(Data!$E:$E,Data!$A:$A,D$2)/SUMIFS(Data!$F:$F,Data!$A:$A,D$2)*3,"") | E14: =IFERROR(SUMIFS(Data!$E:$E,Data!$A:$A,E$2)/SUMIFS(Data!$F:$F,Data!$A:$A,E$2)*3,"") | F14: =IFERROR(SUMIFS(Data!$E:$E,Data!$A:$A,F$2)/SUMIFS(Data!$F:$F,Data!$A:$A,F$2)*3,"") | G14: =IFERROR(SUMIFS(Data!$E:$E,Data!$A:$A,G$2)/SUMIFS(Data!$F:$F,Data!$A:$A,G$2)*3,"") | H14: =IFERROR(SUMIFS(Data!$E:$E,Data!$A:$A,H$2)/SUMIFS(Data!$F:$F,Data!$A:$A,H$2)*3,"") | I14: =IFERROR(SUMIFS(Data!$E:$E,Data!$A:$A,I$2)/SUMIFS(Data!$F:$F,Data!$A:$A,I$2)*3,"") | ... K14: =IFERROR(SUMIFS(Data!$E:$E,Data!$A:$A,K$2)/SUMIFS(Data!$F:$F,Data!$A:$A,K$2)*3,"") | L14: =IFERROR(SUM(Data!$E:$E)/SUM(Data!$F:$F)*3,"") | M14: =IF(COUNT(B14:K14)=0,"",MAX(B14:K14)) | N14: =IF(COUNT(B14:K14)=0,"",MIN(B14:K14)) | O14: =COUNT(B14:K14) | P14: =IF(COUNT(B14:K14)=0,"",INDEX(B14:K14,_xlfn.MAXIFS($B$2:$K$2,B14:K14,">=0"))) | Q14: =IF(COUNT(B14:K14)=0,"","W"&INDEX($B$2:$K$2,MATCH(M14,B14:K14,0)))

Sheet PPD by Week
A1: Player | B1: W1 (9/17) | C1: W2 (9/24) | D1: W3 (10/1) | E1: W4 (10/8) | F1: W5 (10/15) | G1: W6 (10/22) | H1: W7 (10/29) | I1: W8 (11/5) | J1: W9 (11/12) | K1: W10 (11/19) | L1: Season PPD | M1: Best Week | N1: Worst Week | O1: Weeks Played | P1: Latest | Q1: Best Wk
A2: Week # | B2: 1 | C2: 2 | D2: 3 | E2: 4 | F2: 5 | G2: 6 | H2: 7 | I2: 8 | J2: 9 | K2: 10
A3: Mike Broderick | B3: =IFERROR(SUMIFS(Data!$E:$E,Data!$A:$A,B$2,Data!$D:$D,$A3)/SUMIFS(Data!$F:$F,Data!$A:$A,B$2,Data!$D:$D,$A3),"") | C3: =IFERROR(SUMIFS(Data!$E:$E,Data!$A:$A,C$2,Data!$D:$D,$A3)/SUMIFS(Data!$F:$F,Data!$A:$A,C$2,Data!$D:$D,$A3),"") | D3: =IFERROR(SUMIFS(Data!$E:$E,Data!$A:$A,D$2,Data!$D:$D,$A3)/SUMIFS(Data!$F:$F,Data!$A:$A,D$2,Data!$D:$D,$A3),"") | E3: =IFERROR(SUMIFS(Data!$E:$E,Data!$A:$A,E$2,Data!$D:$D,$A3)/SUMIFS(Data!$F:$F,Data!$A:$A,E$2,Data!$D:$D,$A3),"") | F3: =IFERROR(SUMIFS(Data!$E:$E,Data!$A:$A,F$2,Data!$D:$D,$A3)/SUMIFS(Data!$F:$F,Data!$A:$A,F$2,Data!$D:$D,$A3),"") | G3: =IFERROR(SUMIFS(Data!$E:$E,Data!$A:$A,G$2,Data!$D:$D,$A3)/SUMIFS(Data!$F:$F,Data!$A:$A,G$2,Data!$D:$D,$A3),"") | H3: =IFERROR(SUMIFS(Data!$E:$E,Data!$A:$A,H$2,Data!$D:$D,$A3)/SUMIFS(Data!$F:$F,Data!$A:$A,H$2,Data!$D:$D,$A3),"") | I3: =IFERROR(SUMIFS(Data!$E:$E,Data!$A:$A,I$2,Data!$D:$D,$A3)/SUMIFS(Data!$F:$F,Data!$A:$A,I$2,Data!$D:$D,$A3),"") | ... K3: =IFERROR(SUMIFS(Data!$E:$E,Data!$A:$A,K$2,Data!$D:$D,$A3)/SUMIFS(Data!$F:$F,Data!$A:$A,K$2,Data!$D:$D,$A3),"") | L3: =IFERROR(SUMIFS(Data!$E:$E,Data!$D:$D,$A3)/SUMIFS(Data!$F:$F,Data!$D:$D,$A3),"") | M3: =IF(COUNT(B3:K3)=0,"",MAX(B3:K3)) | N3: =IF(COUNT(B3:K3)=0,"",MIN(B3:K3)) | O3: =COUNT(B3:K3) | P3: =IF(COUNT(B3:K3)=0,"",INDEX(B3:K3,_xlfn.MAXIFS($B$2:$K$2,B3:K3,">=0"))) | Q3: =IF(COUNT(B3:K3)=0,"","W"&INDEX($B$2:$K$2,MATCH(M3,B3:K3,0)))
A4: Jeff Broderick | B4: =IFERROR(SUMIFS(Data!$E:$E,Data!$A:$A,B$2,Data!$D:$D,$A4)/SUMIFS(Data!$F:$F,Data!$A:$A,B$2,Data!$D:$D,$A4),"") | C4: =IFERROR(SUMIFS(Data!$E:$E,Data!$A:$A,C$2,Data!$D:$D,$A4)/SUMIFS(Data!$F:$F,Data!$A:$A,C$2,Data!$D:$D,$A4),"") | D4: =IFERROR(SUMIFS(Data!$E:$E,Data!$A:$A,D$2,Data!$D:$D,$A4)/SUMIFS(Data!$F:$F,Data!$A:$A,D$2,Data!$D:$D,$A4),"") | E4: =IFERROR(SUMIFS(Data!$E:$E,Data!$A:$A,E$2,Data!$D:$D,$A4)/SUMIFS(Data!$F:$F,Data!$A:$A,E$2,Data!$D:$D,$A4),"") | F4: =IFERROR(SUMIFS(Data!$E:$E,Data!$A:$A,F$2,Data!$D:$D,$A4)/SUMIFS(Data!$F:$F,Data!$A:$A,F$2,Data!$D:$D,$A4),"") | G4: =IFERROR(SUMIFS(Data!$E:$E,Data!$A:$A,G$2,Data!$D:$D,$A4)/SUMIFS(Data!$F:$F,Data!$A:$A,G$2,Data!$D:$D,$A4),"") | H4: =IFERROR(SUMIFS(Data!$E:$E,Data!$A:$A,H$2,Data!$D:$D,$A4)/SUMIFS(Data!$F:$F,Data!$A:$A,H$2,Data!$D:$D,$A4),"") | I4: =IFERROR(SUMIFS(Data!$E:$E,Data!$A:$A,I$2,Data!$D:$D,$A4)/SUMIFS(Data!$F:$F,Data!$A:$A,I$2,Data!$D:$D,$A4),"") | ... K4: =IFERROR(SUMIFS(Data!$E:$E,Data!$A:$A,K$2,Data!$D:$D,$A4)/SUMIFS(Data!$F:$F,Data!$A:$A,K$2,Data!$D:$D,$A4),"") | L4: =IFERROR(SUMIFS(Data!$E:$E,Data!$D:$D,$A4)/SUMIFS(Data!$F:$F,Data!$D:$D,$A4),"") | M4: =IF(COUNT(B4:K4)=0,"",MAX(B4:K4)) | N4: =IF(COUNT(B4:K4)=0,"",MIN(B4:K4)) | O4: =COUNT(B4:K4) | P4: =IF(COUNT(B4:K4)=0,"",INDEX(B4:K4,_xlfn.MAXIFS($B$2:$K$2,B4:K4,">=0"))) | Q4: =IF(COUNT(B4:K4)=0,"","W"&INDEX($B$2:$K$2,MATCH(M4,B4:K4,0)))
A5: Captain (Vince Clemins) | B5: =IFERROR(SUMIFS(Data!$E:$E,Data!$A:$A,B$2,Data!$D:$D,$A5)/SUMIFS(Data!$F:$F,Data!$A:$A,B$2,Data!$D:$D,$A5),"") | C5: =IFERROR(SUMIFS(Data!$E:$E,Data!$A:$A,C$2,Data!$D:$D,$A5)/SUMIFS(Data!$F:$F,Data!$A:$A,C$2,Data!$D:$D,$A5),"") | D5: =IFERROR(SUMIFS(Data!$E:$E,Data!$A:$A,D$2,Data!$D:$D,$A5)/SUMIFS(Data!$F:$F,Data!$A:$A,D$2,Data!$D:$D,$A5),"") | E5: =IFERROR(SUMIFS(Data!$E:$E,Data!$A:$A,E$2,Data!$D:$D,$A5)/SUMIFS(Data!$F:$F,Data!$A:$A,E$2,Data!$D:$D,$A5),"") | F5: =IFERROR(SUMIFS(Data!$E:$E,Data!$A:$A,F$2,Data!$D:$D,$A5)/SUMIFS(Data!$F:$F,Data!$A:$A,F$2,Data!$D:$D,$A5),"") | G5: =IFERROR(SUMIFS(Data!$E:$E,Data!$A:$A,G$2,Data!$D:$D,$A5)/SUMIFS(Data!$F:$F,Data!$A:$A,G$2,Data!$D:$D,$A5),"") | H5: =IFERROR(SUMIFS(Data!$E:$E,Data!$A:$A,H$2,Data!$D:$D,$A5)/SUMIFS(Data!$F:$F,Data!$A:$A,H$2,Data!$D:$D,$A5),"") | I5: =IFERROR(SUMIFS(Data!$E:$E,Data!$A:$A,I$2,Data!$D:$D,$A5)/SUMIFS(Data!$F:$F,Data!$A:$A,I$2,Data!$D:$D,$A5),"") | ... K5: =IFERROR(SUMIFS(Data!$E:$E,Data!$A:$A,K$2,Data!$D:$D,$A5)/SUMIFS(Data!$F:$F,Data!$A:$A,K$2,Data!$D:$D,$A5),"") | L5: =IFERROR(SUMIFS(Data!$E:$E,Data!$D:$D,$A5)/SUMIFS(Data!$F:$F,Data!$D:$D,$A5),"") | M5: =IF(COUNT(B5:K5)=0,"",MAX(B5:K5)) | N5: =IF(COUNT(B5:K5)=0,"",MIN(B5:K5)) | O5: =COUNT(B5:K5) | P5: =IF(COUNT(B5:K5)=0,"",INDEX(B5:K5,_xlfn.MAXIFS($B$2:$K$2,B5:K5,">=0"))) | Q5: =IF(COUNT(B5:K5)=0,"","W"&INDEX($B$2:$K$2,MATCH(M5,B5:K5,0)))
A6: Al Fromenko | B6: =IFERROR(SUMIFS(Data!$E:$E,Data!$A:$A,B$2,Data!$D:$D,$A6)/SUMIFS(Data!$F:$F,Data!$A:$A,B$2,Data!$D:$D,$A6),"") | C6: =IFERROR(SUMIFS(Data!$E:$E,Data!$A:$A,C$2,Data!$D:$D,$A6)/SUMIFS(Data!$F:$F,Data!$A:$A,C$2,Data!$D:$D,$A6),"") | D6: =IFERROR(SUMIFS(Data!$E:$E,Data!$A:$A,D$2,Data!$D:$D,$A6)/SUMIFS(Data!$F:$F,Data!$A:$A,D$2,Data!$D:$D,$A6),"") | E6: =IFERROR(SUMIFS(Data!$E:$E,Data!$A:$A,E$2,Data!$D:$D,$A6)/SUMIFS(Data!$F:$F,Data!$A:$A,E$2,Data!$D:$D,$A6),"") | F6: =IFERROR(SUMIFS(Data!$E:$E,Data!$A:$A,F$2,Data!$D:$D,$A6)/SUMIFS(Data!$F:$F,Data!$A:$A,F$2,Data!$D:$D,$A6),"") | G6: =IFERROR(SUMIFS(Data!$E:$E,Data!$A:$A,G$2,Data!$D:$D,$A6)/SUMIFS(Data!$F:$F,Data!$A:$A,G$2,Data!$D:$D,$A6),"") | H6: =IFERROR(SUMIFS(Data!$E:$E,Data!$A:$A,H$2,Data!$D:$D,$A6)/SUMIFS(Data!$F:$F,Data!$A:$A,H$2,Data!$D:$D,$A6),"") | I6: =IFERROR(SUMIFS(Data!$E:$E,Data!$A:$A,I$2,Data!$D:$D,$A6)/SUMIFS(Data!$F:$F,Data!$A:$A,I$2,Data!$D:$D,$A6),"") | ... K6: =IFERROR(SUMIFS(Data!$E:$E,Data!$A:$A,K$2,Data!$D:$D,$A6)/SUMIFS(Data!$F:$F,Data!$A:$A,K$2,Data!$D:$D,$A6),"") | L6: =IFERROR(SUMIFS(Data!$E:$E,Data!$D:$D,$A6)/SUMIFS(Data!$F:$F,Data!$D:$D,$A6),"") | M6: =IF(COUNT(B6:K6)=0,"",MAX(B6:K6)) | N6: =IF(COUNT(B6:K6)=0,"",MIN(B6:K6)) | O6: =COUNT(B6:K6) | P6: =IF(COUNT(B6:K6)=0,"",INDEX(B6:K6,_xlfn.MAXIFS($B$2:$K$2,B6:K6,">=0"))) | Q6: =IF(COUNT(B6:K6)=0,"","W"&INDEX($B$2:$K$2,MATCH(M6,B6:K6,0)))
A7: Bill Prelle | B7: =IFERROR(SUMIFS(Data!$E:$E,Data!$A:$A,B$2,Data!$D:$D,$A7)/SUMIFS(Data!$F:$F,Data!$A:$A,B$2,Data!$D:$D,$A7),"") | C7: =IFERROR(SUMIFS(Data!$E:$E,Data!$A:$A,C$2,Data!$D:$D,$A7)/SUMIFS(Data!$F:$F,Data!$A:$A,C$2,Data!$D:$D,$A7),"") | D7: =IFERROR(SUMIFS(Data!$E:$E,Data!$A:$A,D$2,Data!$D:$D,$A7)/SUMIFS(Data!$F:$F,Data!$A:$A,D$2,Data!$D:$D,$A7),"") | E7: =IFERROR(SUMIFS(Data!$E:$E,Data!$A:$A,E$2,Data!$D:$D,$A7)/SUMIFS(Data!$F:$F,Data!$A:$A,E$2,Data!$D:$D,$A7),"") | F7: =IFERROR(SUMIFS(Data!$E:$E,Data!$A:$A,F$2,Data!$D:$D,$A7)/SUMIFS(Data!$F:$F,Data!$A:$A,F$2,Data!$D:$D,$A7),"") | G7: =IFERROR(SUMIFS(Data!$E:$E,Data!$A:$A,G$2,Data!$D:$D,$A7)/SUMIFS(Data!$F:$F,Data!$A:$A,G$2,Data!$D:$D,$A7),"") | H7: =IFERROR(SUMIFS(Data!$E:$E,Data!$A:$A,H$2,Data!$D:$D,$A7)/SUMIFS(Data!$F:$F,Data!$A:$A,H$2,Data!$D:$D,$A7),"") | I7: =IFERROR(SUMIFS(Data!$E:$E,Data!$A:$A,I$2,Data!$D:$D,$A7)/SUMIFS(Data!$F:$F,Data!$A:$A,I$2,Data!$D:$D,$A7),"") | ... K7: =IFERROR(SUMIFS(Data!$E:$E,Data!$A:$A,K$2,Data!$D:$D,$A7)/SUMIFS(Data!$F:$F,Data!$A:$A,K$2,Data!$D:$D,$A7),"") | L7: =IFERROR(SUMIFS(Data!$E:$E,Data!$D:$D,$A7)/SUMIFS(Data!$F:$F,Data!$D:$D,$A7),"") | M7: =IF(COUNT(B7:K7)=0,"",MAX(B7:K7)) | N7: =IF(COUNT(B7:K7)=0,"",MIN(B7:K7)) | O7: =COUNT(B7:K7) | P7: =IF(COUNT(B7:K7)=0,"",INDEX(B7:K7,_xlfn.MAXIFS($B$2:$K$2,B7:K7,">=0"))) | Q7: =IF(COUNT(B7:K7)=0,"","W"&INDEX($B$2:$K$2,MATCH(M7,B7:K7,0)))
A8: Keith McCarthy | B8: =IFERROR(SUMIFS(Data!$E:$E,Data!$A:$A,B$2,Data!$D:$D,$A8)/SUMIFS(Data!$F:$F,Data!$A:$A,B$2,Data!$D:$D,$A8),"") | C8: =IFERROR(SUMIFS(Data!$E:$E,Data!$A:$A,C$2,Data!$D:$D,$A8)/SUMIFS(Data!$F:$F,Data!$A:$A,C$2,Data!$D:$D,$A8),"") | D8: =IFERROR(SUMIFS(Data!$E:$E,Data!$A:$A,D$2,Data!$D:$D,$A8)/SUMIFS(Data!$F:$F,Data!$A:$A,D$2,Data!$D:$D,$A8),"") | E8: =IFERROR(SUMIFS(Data!$E:$E,Data!$A:$A,E$2,Data!$D:$D,$A8)/SUMIFS(Data!$F:$F,Data!$A:$A,E$2,Data!$D:$D,$A8),"") | F8: =IFERROR(SUMIFS(Data!$E:$E,Data!$A:$A,F$2,Data!$D:$D,$A8)/SUMIFS(Data!$F:$F,Data!$A:$A,F$2,Data!$D:$D,$A8),"") | G8: =IFERROR(SUMIFS(Data!$E:$E,Data!$A:$A,G$2,Data!$D:$D,$A8)/SUMIFS(Data!$F:$F,Data!$A:$A,G$2,Data!$D:$D,$A8),"") | H8: =IFERROR(SUMIFS(Data!$E:$E,Data!$A:$A,H$2,Data!$D:$D,$A8)/SUMIFS(Data!$F:$F,Data!$A:$A,H$2,Data!$D:$D,$A8),"") | I8: =IFERROR(SUMIFS(Data!$E:$E,Data!$A:$A,I$2,Data!$D:$D,$A8)/SUMIFS(Data!$F:$F,Data!$A:$A,I$2,Data!$D:$D,$A8),"") | ... K8: =IFERROR(SUMIFS(Data!$E:$E,Data!$A:$A,K$2,Data!$D:$D,$A8)/SUMIFS(Data!$F:$F,Data!$A:$A,K$2,Data!$D:$D,$A8),"") | L8: =IFERROR(SUMIFS(Data!$E:$E,Data!$D:$D,$A8)/SUMIFS(Data!$F:$F,Data!$D:$D,$A8),"") | M8: =IF(COUNT(B8:K8)=0,"",MAX(B8:K8)) | N8: =IF(COUNT(B8:K8)=0,"",MIN(B8:K8)) | O8: =COUNT(B8:K8) | P8: =IF(COUNT(B8:K8)=0,"",INDEX(B8:K8,_xlfn.MAXIFS($B$2:$K$2,B8:K8,">=0"))) | Q8: =IF(COUNT(B8:K8)=0,"","W"&INDEX($B$2:$K$2,MATCH(M8,B8:K8,0)))
A9: Tom Davis | B9: =IFERROR(SUMIFS(Data!$E:$E,Data!$A:$A,B$2,Data!$D:$D,$A9)/SUMIFS(Data!$F:$F,Data!$A:$A,B$2,Data!$D:$D,$A9),"") | C9: =IFERROR(SUMIFS(Data!$E:$E,Data!$A:$A,C$2,Data!$D:$D,$A9)/SUMIFS(Data!$F:$F,Data!$A:$A,C$2,Data!$D:$D,$A9),"") | D9: =IFERROR(SUMIFS(Data!$E:$E,Data!$A:$A,D$2,Data!$D:$D,$A9)/SUMIFS(Data!$F:$F,Data!$A:$A,D$2,Data!$D:$D,$A9),"") | E9: =IFERROR(SUMIFS(Data!$E:$E,Data!$A:$A,E$2,Data!$D:$D,$A9)/SUMIFS(Data!$F:$F,Data!$A:$A,E$2,Data!$D:$D,$A9),"") | F9: =IFERROR(SUMIFS(Data!$E:$E,Data!$A:$A,F$2,Data!$D:$D,$A9)/SUMIFS(Data!$F:$F,Data!$A:$A,F$2,Data!$D:$D,$A9),"") | G9: =IFERROR(SUMIFS(Data!$E:$E,Data!$A:$A,G$2,Data!$D:$D,$A9)/SUMIFS(Data!$F:$F,Data!$A:$A,G$2,Data!$D:$D,$A9),"") | H9: =IFERROR(SUMIFS(Data!$E:$E,Data!$A:$A,H$2,Data!$D:$D,$A9)/SUMIFS(Data!$F:$F,Data!$A:$A,H$2,Data!$D:$D,$A9),"") | I9: =IFERROR(SUMIFS(Data!$E:$E,Data!$A:$A,I$2,Data!$D:$D,$A9)/SUMIFS(Data!$F:$F,Data!$A:$A,I$2,Data!$D:$D,$A9),"") | ... K9: =IFERROR(SUMIFS(Data!$E:$E,Data!$A:$A,K$2,Data!$D:$D,$A9)/SUMIFS(Data!$F:$F,Data!$A:$A,K$2,Data!$D:$D,$A9),"") | L9: =IFERROR(SUMIFS(Data!$E:$E,Data!$D:$D,$A9)/SUMIFS(Data!$F:$F,Data!$D:$D,$A9),"") | M9: =IF(COUNT(B9:K9)=0,"",MAX(B9:K9)) | N9: =IF(COUNT(B9:K9)=0,"",MIN(B9:K9)) | O9: =COUNT(B9:K9) | P9: =IF(COUNT(B9:K9)=0,"",INDEX(B9:K9,_xlfn.MAXIFS($B$2:$K$2,B9:K9,">=0"))) | Q9: =IF(COUNT(B9:K9)=0,"","W"&INDEX($B$2:$K$2,MATCH(M9,B9:K9,0)))
A10: John Klemick | B10: =IFERROR(SUMIFS(Data!$E:$E,Data!$A:$A,B$2,Data!$D:$D,$A10)/SUMIFS(Data!$F:$F,Data!$A:$A,B$2,Data!$D:$D,$A10),"") | C10: =IFERROR(SUMIFS(Data!$E:$E,Data!$A:$A,C$2,Data!$D:$D,$A10)/SUMIFS(Data!$F:$F,Data!$A:$A,C$2,Data!$D:$D,$A10),"") | D10: =IFERROR(SUMIFS(Data!$E:$E,Data!$A:$A,D$2,Data!$D:$D,$A10)/SUMIFS(Data!$F:$F,Data!$A:$A,D$2,Data!$D:$D,$A10),"") | E10: =IFERROR(SUMIFS(Data!$E:$E,Data!$A:$A,E$2,Data!$D:$D,$A10)/SUMIFS(Data!$F:$F,Data!$A:$A,E$2,Data!$D:$D,$A10),"") | F10: =IFERROR(SUMIFS(Data!$E:$E,Data!$A:$A,F$2,Data!$D:$D,$A10)/SUMIFS(Data!$F:$F,Data!$A:$A,F$2,Data!$D:$D,$A10),"") | G10: =IFERROR(SUMIFS(Data!$E:$E,Data!$A:$A,G$2,Data!$D:$D,$A10)/SUMIFS(Data!$F:$F,Data!$A:$A,G$2,Data!$D:$D,$A10),"") | H10: =IFERROR(SUMIFS(Data!$E:$E,Data!$A:$A,H$2,Data!$D:$D,$A10)/SUMIFS(Data!$F:$F,Data!$A:$A,H$2,Data!$D:$D,$A10),"") | I10: =IFERROR(SUMIFS(Data!$E:$E,Data!$A:$A,I$2,Data!$D:$D,$A10)/SUMIFS(Data!$F:$F,Data!$A:$A,I$2,Data!$D:$D,$A10),"") | ... K10: =IFERROR(SUMIFS(Data!$E:$E,Data!$A:$A,K$2,Data!$D:$D,$A10)/SUMIFS(Data!$F:$F,Data!$A:$A,K$2,Data!$D:$D,$A10),"") | L10: =IFERROR(SUMIFS(Data!$E:$E,Data!$D:$D,$A10)/SUMIFS(Data!$F:$F,Data!$D:$D,$A10),"") | M10: =IF(COUNT(B10:K10)=0,"",MAX(B10:K10)) | N10: =IF(COUNT(B10:K10)=0,"",MIN(B10:K10)) | O10: =COUNT(B10:K10) | P10: =IF(COUNT(B10:K10)=0,"",INDEX(B10:K10,_xlfn.MAXIFS($B$2:$K$2,B10:K10,">=0"))) | Q10: =IF(COUNT(B10:K10)=0,"","W"&INDEX($B$2:$K$2,MATCH(M10,B10:K10,0)))
A11: Frank Gillespie | B11: =IFERROR(SUMIFS(Data!$E:$E,Data!$A:$A,B$2,Data!$D:$D,$A11)/SUMIFS(Data!$F:$F,Data!$A:$A,B$2,Data!$D:$D,$A11),"") | C11: =IFERROR(SUMIFS(Data!$E:$E,Data!$A:$A,C$2,Data!$D:$D,$A11)/SUMIFS(Data!$F:$F,Data!$A:$A,C$2,Data!$D:$D,$A11),"") | D11: =IFERROR(SUMIFS(Data!$E:$E,Data!$A:$A,D$2,Data!$D:$D,$A11)/SUMIFS(Data!$F:$F,Data!$A:$A,D$2,Data!$D:$D,$A11),"") | E11: =IFERROR(SUMIFS(Data!$E:$E,Data!$A:$A,E$2,Data!$D:$D,$A11)/SUMIFS(Data!$F:$F,Data!$A:$A,E$2,Data!$D:$D,$A11),"") | F11: =IFERROR(SUMIFS(Data!$E:$E,Data!$A:$A,F$2,Data!$D:$D,$A11)/SUMIFS(Data!$F:$F,Data!$A:$A,F$2,Data!$D:$D,$A11),"") | G11: =IFERROR(SUMIFS(Data!$E:$E,Data!$A:$A,G$2,Data!$D:$D,$A11)/SUMIFS(Data!$F:$F,Data!$A:$A,G$2,Data!$D:$D,$A11),"") | H11: =IFERROR(SUMIFS(Data!$E:$E,Data!$A:$A,H$2,Data!$D:$D,$A11)/SUMIFS(Data!$F:$F,Data!$A:$A,H$2,Data!$D:$D,$A11),"") | I11: =IFERROR(SUMIFS(Data!$E:$E,Data!$A:$A,I$2,Data!$D:$D,$A11)/SUMIFS(Data!$F:$F,Data!$A:$A,I$2,Data!$D:$D,$A11),"") | ... K11: =IFERROR(SUMIFS(Data!$E:$E,Data!$A:$A,K$2,Data!$D:$D,$A11)/SUMIFS(Data!$F:$F,Data!$A:$A,K$2,Data!$D:$D,$A11),"") | L11: =IFERROR(SUMIFS(Data!$E:$E,Data!$D:$D,$A11)/SUMIFS(Data!$F:$F,Data!$D:$D,$A11),"") | M11: =IF(COUNT(B11:K11)=0,"",MAX(B11:K11)) | N11: =IF(COUNT(B11:K11)=0,"",MIN(B11:K11)) | O11: =COUNT(B11:K11) | P11: =IF(COUNT(B11:K11)=0,"",INDEX(B11:K11,_xlfn.MAXIFS($B$2:$K$2,B11:K11,">=0"))) | Q11: =IF(COUNT(B11:K11)=0,"","W"&INDEX($B$2:$K$2,MATCH(M11,B11:K11,0)))
A12: Jim Wright | B12: =IFERROR(SUMIFS(Data!$E:$E,Data!$A:$A,B$2,Data!$D:$D,$A12)/SUMIFS(Data!$F:$F,Data!$A:$A,B$2,Data!$D:$D,$A12),"") | C12: =IFERROR(SUMIFS(Data!$E:$E,Data!$A:$A,C$2,Data!$D:$D,$A12)/SUMIFS(Data!$F:$F,Data!$A:$A,C$2,Data!$D:$D,$A12),"") | D12: =IFERROR(SUMIFS(Data!$E:$E,Data!$A:$A,D$2,Data!$D:$D,$A12)/SUMIFS(Data!$F:$F,Data!$A:$A,D$2,Data!$D:$D,$A12),"") | E12: =IFERROR(SUMIFS(Data!$E:$E,Data!$A:$A,E$2,Data!$D:$D,$A12)/SUMIFS(Data!$F:$F,Data!$A:$A,E$2,Data!$D:$D,$A12),"") | F12: =IFERROR(SUMIFS(Data!$E:$E,Data!$A:$A,F$2,Data!$D:$D,$A12)/SUMIFS(Data!$F:$F,Data!$A:$A,F$2,Data!$D:$D,$A12),"") | G12: =IFERROR(SUMIFS(Data!$E:$E,Data!$A:$A,G$2,Data!$D:$D,$A12)/SUMIFS(Data!$F:$F,Data!$A:$A,G$2,Data!$D:$D,$A12),"") | H12: =IFERROR(SUMIFS(Data!$E:$E,Data!$A:$A,H$2,Data!$D:$D,$A12)/SUMIFS(Data!$F:$F,Data!$A:$A,H$2,Data!$D:$D,$A12),"") | I12: =IFERROR(SUMIFS(Data!$E:$E,Data!$A:$A,I$2,Data!$D:$D,$A12)/SUMIFS(Data!$F:$F,Data!$A:$A,I$2,Data!$D:$D,$A12),"") | ... K12: =IFERROR(SUMIFS(Data!$E:$E,Data!$A:$A,K$2,Data!$D:$D,$A12)/SUMIFS(Data!$F:$F,Data!$A:$A,K$2,Data!$D:$D,$A12),"") | L12: =IFERROR(SUMIFS(Data!$E:$E,Data!$D:$D,$A12)/SUMIFS(Data!$F:$F,Data!$D:$D,$A12),"") | M12: =IF(COUNT(B12:K12)=0,"",MAX(B12:K12)) | N12: =IF(COUNT(B12:K12)=0,"",MIN(B12:K12)) | O12: =COUNT(B12:K12) | P12: =IF(COUNT(B12:K12)=0,"",INDEX(B12:K12,_xlfn.MAXIFS($B$2:$K$2,B12:K12,">=0"))) | Q12: =IF(COUNT(B12:K12)=0,"","W"&INDEX($B$2:$K$2,MATCH(M12,B12:K12,0)))
A13: Dave Keppler | B13: =IFERROR(SUMIFS(Data!$E:$E,Data!$A:$A,B$2,Data!$D:$D,$A13)/SUMIFS(Data!$F:$F,Data!$A:$A,B$2,Data!$D:$D,$A13),"") | C13: =IFERROR(SUMIFS(Data!$E:$E,Data!$A:$A,C$2,Data!$D:$D,$A13)/SUMIFS(Data!$F:$F,Data!$A:$A,C$2,Data!$D:$D,$A13),"") | D13: =IFERROR(SUMIFS(Data!$E:$E,Data!$A:$A,D$2,Data!$D:$D,$A13)/SUMIFS(Data!$F:$F,Data!$A:$A,D$2,Data!$D:$D,$A13),"") | E13: =IFERROR(SUMIFS(Data!$E:$E,Data!$A:$A,E$2,Data!$D:$D,$A13)/SUMIFS(Data!$F:$F,Data!$A:$A,E$2,Data!$D:$D,$A13),"") | F13: =IFERROR(SUMIFS(Data!$E:$E,Data!$A:$A,F$2,Data!$D:$D,$A13)/SUMIFS(Data!$F:$F,Data!$A:$A,F$2,Data!$D:$D,$A13),"") | G13: =IFERROR(SUMIFS(Data!$E:$E,Data!$A:$A,G$2,Data!$D:$D,$A13)/SUMIFS(Data!$F:$F,Data!$A:$A,G$2,Data!$D:$D,$A13),"") | H13: =IFERROR(SUMIFS(Data!$E:$E,Data!$A:$A,H$2,Data!$D:$D,$A13)/SUMIFS(Data!$F:$F,Data!$A:$A,H$2,Data!$D:$D,$A13),"") | I13: =IFERROR(SUMIFS(Data!$E:$E,Data!$A:$A,I$2,Data!$D:$D,$A13)/SUMIFS(Data!$F:$F,Data!$A:$A,I$2,Data!$D:$D,$A13),"") | ... K13: =IFERROR(SUMIFS(Data!$E:$E,Data!$A:$A,K$2,Data!$D:$D,$A13)/SUMIFS(Data!$F:$F,Data!$A:$A,K$2,Data!$D:$D,$A13),"") | L13: =IFERROR(SUMIFS(Data!$E:$E,Data!$D:$D,$A13)/SUMIFS(Data!$F:$F,Data!$D:$D,$A13),"") | M13: =IF(COUNT(B13:K13)=0,"",MAX(B13:K13)) | N13: =IF(COUNT(B13:K13)=0,"",MIN(B13:K13)) | O13: =COUNT(B13:K13) | P13: =IF(COUNT(B13:K13)=0,"",INDEX(B13:K13,_xlfn.MAXIFS($B$2:$K$2,B13:K13,">=0"))) | Q13: =IF(COUNT(B13:K13)=0,"","W"&INDEX($B$2:$K$2,MATCH(M13,B13:K13,0)))
A14: TEAM | B14: =IFERROR(SUMIFS(Data!$E:$E,Data!$A:$A,B$2)/SUMIFS(Data!$F:$F,Data!$A:$A,B$2),"") | C14: =IFERROR(SUMIFS(Data!$E:$E,Data!$A:$A,C$2)/SUMIFS(Data!$F:$F,Data!$A:$A,C$2),"") | D14: =IFERROR(SUMIFS(Data!$E:$E,Data!$A:$A,D$2)/SUMIFS(Data!$F:$F,Data!$A:$A,D$2),"") | E14: =IFERROR(SUMIFS(Data!$E:$E,Data!$A:$A,E$2)/SUMIFS(Data!$F:$F,Data!$A:$A,E$2),"") | F14: =IFERROR(SUMIFS(Data!$E:$E,Data!$A:$A,F$2)/SUMIFS(Data!$F:$F,Data!$A:$A,F$2),"") | G14: =IFERROR(SUMIFS(Data!$E:$E,Data!$A:$A,G$2)/SUMIFS(Data!$F:$F,Data!$A:$A,G$2),"") | H14: =IFERROR(SUMIFS(Data!$E:$E,Data!$A:$A,H$2)/SUMIFS(Data!$F:$F,Data!$A:$A,H$2),"") | I14: =IFERROR(SUMIFS(Data!$E:$E,Data!$A:$A,I$2)/SUMIFS(Data!$F:$F,Data!$A:$A,I$2),"") | ... K14: =IFERROR(SUMIFS(Data!$E:$E,Data!$A:$A,K$2)/SUMIFS(Data!$F:$F,Data!$A:$A,K$2),"") | L14: =IFERROR(SUM(Data!$E:$E)/SUM(Data!$F:$F),"") | M14: =IF(COUNT(B14:K14)=0,"",MAX(B14:K14)) | N14: =IF(COUNT(B14:K14)=0,"",MIN(B14:K14)) | O14: =COUNT(B14:K14) | P14: =IF(COUNT(B14:K14)=0,"",INDEX(B14:K14,_xlfn.MAXIFS($B$2:$K$2,B14:K14,">=0"))) | Q14: =IF(COUNT(B14:K14)=0,"","W"&INDEX($B$2:$K$2,MATCH(M14,B14:K14,0)))

Sheet % Change
A1: Player | B1: W1 (9/17) | C1: W2 (9/24) | D1: W3 (10/1) | E1: W4 (10/8) | F1: W5 (10/15) | G1: W6 (10/22) | H1: W7 (10/29) | I1: W8 (11/5) | J1: W9 (11/12) | K1: W10 (11/19)
A2: Week # | B2: 1 | C2: 2 | D2: 3 | E2: 4 | F2: 5 | G2: 6 | H2: 7 | I2: 8 | J2: 9 | K2: 10
A3: Mike Broderick | C3: =IF(NOT(ISNUMBER('3DA by Week'!C3)),"",IF(_xlfn.MAXIFS('3DA by Week'!$B$2:B$2,'3DA by Week'!$B3:B3,">=0")=0,"",'3DA by Week'!C3/INDEX('3DA by Week'!$B3:$K3,_xlfn.MAXIFS('3DA by Week'!$B$2:B$2,'3DA by Week'!$B3:B3,">=0"))-1)) | D3: =IF(NOT(ISNUMBER('3DA by Week'!D3)),"",IF(_xlfn.MAXIFS('3DA by Week'!$B$2:C$2,'3DA by Week'!$B3:C3,">=0")=0,"",'3DA by Week'!D3/INDEX('3DA by Week'!$B3:$K3,_xlfn.MAXIFS('3DA by Week'!$B$2:C$2,'3DA by Week'!$B3:C3,">=0"))-1)) | E3: =IF(NOT(ISNUMBER('3DA by Week'!E3)),"",IF(_xlfn.MAXIFS('3DA by Week'!$B$2:D$2,'3DA by Week'!$B3:D3,">=0")=0,"",'3DA by Week'!E3/INDEX('3DA by Week'!$B3:$K3,_xlfn.MAXIFS('3DA by Week'!$B$2:D$2,'3DA by Week'!$B3:D3,">=0"))-1)) | F3: =IF(NOT(ISNUMBER('3DA by Week'!F3)),"",IF(_xlfn.MAXIFS('3DA by Week'!$B$2:E$2,'3DA by Week'!$B3:E3,">=0")=0,"",'3DA by Week'!F3/INDEX('3DA by Week'!$B3:$K3,_xlfn.MAXIFS('3DA by Week'!$B$2:E$2,'3DA by Week'!$B3:E3,">=0"))-1)) | G3: =IF(NOT(ISNUMBER('3DA by Week'!G3)),"",IF(_xlfn.MAXIFS('3DA by Week'!$B$2:F$2,'3DA by Week'!$B3:F3,">=0")=0,"",'3DA by Week'!G3/INDEX('3DA by Week'!$B3:$K3,_xlfn.MAXIFS('3DA by Week'!$B$2:F$2,'3DA by Week'!$B3:F3,">=0"))-1)) | H3: =IF(NOT(ISNUMBER('3DA by Week'!H3)),"",IF(_xlfn.MAXIFS('3DA by Week'!$B$2:G$2,'3DA by Week'!$B3:G3,">=0")=0,"",'3DA by Week'!H3/INDEX('3DA by Week'!$B3:$K3,_xlfn.MAXIFS('3DA by Week'!$B$2:G$2,'3DA by Week'!$B3:G3,">=0"))-1)) | I3: =IF(NOT(ISNUMBER('3DA by Week'!I3)),"",IF(_xlfn.MAXIFS('3DA by Week'!$B$2:H$2,'3DA by Week'!$B3:H3,">=0")=0,"",'3DA by Week'!I3/INDEX('3DA by Week'!$B3:$K3,_xlfn.MAXIFS('3DA by Week'!$B$2:H$2,'3DA by Week'!$B3:H3,">=0"))-1)) | J3: =IF(NOT(ISNUMBER('3DA by Week'!J3)),"",IF(_xlfn.MAXIFS('3DA by Week'!$B$2:I$2,'3DA by Week'!$B3:I3,">=0")=0,"",'3DA by Week'!J3/INDEX('3DA by Week'!$B3:$K3,_xlfn.MAXIFS('3DA by Week'!$B$2:I$2,'3DA by Week'!$B3:I3,">=0"))-1)) | K3: =IF(NOT(ISNUMBER('3DA by Week'!K3)),"",IF(_xlfn.MAXIFS('3DA by Week'!$B$2:J$2,'3DA by Week'!$B3:J3,">=0")=0,"",'3DA by Week'!K3/INDEX('3DA by Week'!$B3:$K3,_xlfn.MAXIFS('3DA by Week'!$B$2:J$2,'3DA by Week'!$B3:J3,">=0"))-1))
A4: Jeff Broderick | C4: =IF(NOT(ISNUMBER('3DA by Week'!C4)),"",IF(_xlfn.MAXIFS('3DA by Week'!$B$2:B$2,'3DA by Week'!$B4:B4,">=0")=0,"",'3DA by Week'!C4/INDEX('3DA by Week'!$B4:$K4,_xlfn.MAXIFS('3DA by Week'!$B$2:B$2,'3DA by Week'!$B4:B4,">=0"))-1)) | D4: =IF(NOT(ISNUMBER('3DA by Week'!D4)),"",IF(_xlfn.MAXIFS('3DA by Week'!$B$2:C$2,'3DA by Week'!$B4:C4,">=0")=0,"",'3DA by Week'!D4/INDEX('3DA by Week'!$B4:$K4,_xlfn.MAXIFS('3DA by Week'!$B$2:C$2,'3DA by Week'!$B4:C4,">=0"))-1)) | E4: =IF(NOT(ISNUMBER('3DA by Week'!E4)),"",IF(_xlfn.MAXIFS('3DA by Week'!$B$2:D$2,'3DA by Week'!$B4:D4,">=0")=0,"",'3DA by Week'!E4/INDEX('3DA by Week'!$B4:$K4,_xlfn.MAXIFS('3DA by Week'!$B$2:D$2,'3DA by Week'!$B4:D4,">=0"))-1)) | F4: =IF(NOT(ISNUMBER('3DA by Week'!F4)),"",IF(_xlfn.MAXIFS('3DA by Week'!$B$2:E$2,'3DA by Week'!$B4:E4,">=0")=0,"",'3DA by Week'!F4/INDEX('3DA by Week'!$B4:$K4,_xlfn.MAXIFS('3DA by Week'!$B$2:E$2,'3DA by Week'!$B4:E4,">=0"))-1)) | G4: =IF(NOT(ISNUMBER('3DA by Week'!G4)),"",IF(_xlfn.MAXIFS('3DA by Week'!$B$2:F$2,'3DA by Week'!$B4:F4,">=0")=0,"",'3DA by Week'!G4/INDEX('3DA by Week'!$B4:$K4,_xlfn.MAXIFS('3DA by Week'!$B$2:F$2,'3DA by Week'!$B4:F4,">=0"))-1)) | H4: =IF(NOT(ISNUMBER('3DA by Week'!H4)),"",IF(_xlfn.MAXIFS('3DA by Week'!$B$2:G$2,'3DA by Week'!$B4:G4,">=0")=0,"",'3DA by Week'!H4/INDEX('3DA by Week'!$B4:$K4,_xlfn.MAXIFS('3DA by Week'!$B$2:G$2,'3DA by Week'!$B4:G4,">=0"))-1)) | I4: =IF(NOT(ISNUMBER('3DA by Week'!I4)),"",IF(_xlfn.MAXIFS('3DA by Week'!$B$2:H$2,'3DA by Week'!$B4:H4,">=0")=0,"",'3DA by Week'!I4/INDEX('3DA by Week'!$B4:$K4,_xlfn.MAXIFS('3DA by Week'!$B$2:H$2,'3DA by Week'!$B4:H4,">=0"))-1)) | J4: =IF(NOT(ISNUMBER('3DA by Week'!J4)),"",IF(_xlfn.MAXIFS('3DA by Week'!$B$2:I$2,'3DA by Week'!$B4:I4,">=0")=0,"",'3DA by Week'!J4/INDEX('3DA by Week'!$B4:$K4,_xlfn.MAXIFS('3DA by Week'!$B$2:I$2,'3DA by Week'!$B4:I4,">=0"))-1)) | K4: =IF(NOT(ISNUMBER('3DA by Week'!K4)),"",IF(_xlfn.MAXIFS('3DA by Week'!$B$2:J$2,'3DA by Week'!$B4:J4,">=0")=0,"",'3DA by Week'!K4/INDEX('3DA by Week'!$B4:$K4,_xlfn.MAXIFS('3DA by Week'!$B$2:J$2,'3DA by Week'!$B4:J4,">=0"))-1))
A5: Captain (Vince Clemins) | C5: =IF(NOT(ISNUMBER('3DA by Week'!C5)),"",IF(_xlfn.MAXIFS('3DA by Week'!$B$2:B$2,'3DA by Week'!$B5:B5,">=0")=0,"",'3DA by Week'!C5/INDEX('3DA by Week'!$B5:$K5,_xlfn.MAXIFS('3DA by Week'!$B$2:B$2,'3DA by Week'!$B5:B5,">=0"))-1)) | D5: =IF(NOT(ISNUMBER('3DA by Week'!D5)),"",IF(_xlfn.MAXIFS('3DA by Week'!$B$2:C$2,'3DA by Week'!$B5:C5,">=0")=0,"",'3DA by Week'!D5/INDEX('3DA by Week'!$B5:$K5,_xlfn.MAXIFS('3DA by Week'!$B$2:C$2,'3DA by Week'!$B5:C5,">=0"))-1)) | E5: =IF(NOT(ISNUMBER('3DA by Week'!E5)),"",IF(_xlfn.MAXIFS('3DA by Week'!$B$2:D$2,'3DA by Week'!$B5:D5,">=0")=0,"",'3DA by Week'!E5/INDEX('3DA by Week'!$B5:$K5,_xlfn.MAXIFS('3DA by Week'!$B$2:D$2,'3DA by Week'!$B5:D5,">=0"))-1)) | F5: =IF(NOT(ISNUMBER('3DA by Week'!F5)),"",IF(_xlfn.MAXIFS('3DA by Week'!$B$2:E$2,'3DA by Week'!$B5:E5,">=0")=0,"",'3DA by Week'!F5/INDEX('3DA by Week'!$B5:$K5,_xlfn.MAXIFS('3DA by Week'!$B$2:E$2,'3DA by Week'!$B5:E5,">=0"))-1)) | G5: =IF(NOT(ISNUMBER('3DA by Week'!G5)),"",IF(_xlfn.MAXIFS('3DA by Week'!$B$2:F$2,'3DA by Week'!$B5:F5,">=0")=0,"",'3DA by Week'!G5/INDEX('3DA by Week'!$B5:$K5,_xlfn.MAXIFS('3DA by Week'!$B$2:F$2,'3DA by Week'!$B5:F5,">=0"))-1)) | H5: =IF(NOT(ISNUMBER('3DA by Week'!H5)),"",IF(_xlfn.MAXIFS('3DA by Week'!$B$2:G$2,'3DA by Week'!$B5:G5,">=0")=0,"",'3DA by Week'!H5/INDEX('3DA by Week'!$B5:$K5,_xlfn.MAXIFS('3DA by Week'!$B$2:G$2,'3DA by Week'!$B5:G5,">=0"))-1)) | I5: =IF(NOT(ISNUMBER('3DA by Week'!I5)),"",IF(_xlfn.MAXIFS('3DA by Week'!$B$2:H$2,'3DA by Week'!$B5:H5,">=0")=0,"",'3DA by Week'!I5/INDEX('3DA by Week'!$B5:$K5,_xlfn.MAXIFS('3DA by Week'!$B$2:H$2,'3DA by Week'!$B5:H5,">=0"))-1)) | J5: =IF(NOT(ISNUMBER('3DA by Week'!J5)),"",IF(_xlfn.MAXIFS('3DA by Week'!$B$2:I$2,'3DA by Week'!$B5:I5,">=0")=0,"",'3DA by Week'!J5/INDEX('3DA by Week'!$B5:$K5,_xlfn.MAXIFS('3DA by Week'!$B$2:I$2,'3DA by Week'!$B5:I5,">=0"))-1)) | K5: =IF(NOT(ISNUMBER('3DA by Week'!K5)),"",IF(_xlfn.MAXIFS('3DA by Week'!$B$2:J$2,'3DA by Week'!$B5:J5,">=0")=0,"",'3DA by Week'!K5/INDEX('3DA by Week'!$B5:$K5,_xlfn.MAXIFS('3DA by Week'!$B$2:J$2,'3DA by Week'!$B5:J5,">=0"))-1))
A6: Al Fromenko | C6: =IF(NOT(ISNUMBER('3DA by Week'!C6)),"",IF(_xlfn.MAXIFS('3DA by Week'!$B$2:B$2,'3DA by Week'!$B6:B6,">=0")=0,"",'3DA by Week'!C6/INDEX('3DA by Week'!$B6:$K6,_xlfn.MAXIFS('3DA by Week'!$B$2:B$2,'3DA by Week'!$B6:B6,">=0"))-1)) | D6: =IF(NOT(ISNUMBER('3DA by Week'!D6)),"",IF(_xlfn.MAXIFS('3DA by Week'!$B$2:C$2,'3DA by Week'!$B6:C6,">=0")=0,"",'3DA by Week'!D6/INDEX('3DA by Week'!$B6:$K6,_xlfn.MAXIFS('3DA by Week'!$B$2:C$2,'3DA by Week'!$B6:C6,">=0"))-1)) | E6: =IF(NOT(ISNUMBER('3DA by Week'!E6)),"",IF(_xlfn.MAXIFS('3DA by Week'!$B$2:D$2,'3DA by Week'!$B6:D6,">=0")=0,"",'3DA by Week'!E6/INDEX('3DA by Week'!$B6:$K6,_xlfn.MAXIFS('3DA by Week'!$B$2:D$2,'3DA by Week'!$B6:D6,">=0"))-1)) | F6: =IF(NOT(ISNUMBER('3DA by Week'!F6)),"",IF(_xlfn.MAXIFS('3DA by Week'!$B$2:E$2,'3DA by Week'!$B6:E6,">=0")=0,"",'3DA by Week'!F6/INDEX('3DA by Week'!$B6:$K6,_xlfn.MAXIFS('3DA by Week'!$B$2:E$2,'3DA by Week'!$B6:E6,">=0"))-1)) | G6: =IF(NOT(ISNUMBER('3DA by Week'!G6)),"",IF(_xlfn.MAXIFS('3DA by Week'!$B$2:F$2,'3DA by Week'!$B6:F6,">=0")=0,"",'3DA by Week'!G6/INDEX('3DA by Week'!$B6:$K6,_xlfn.MAXIFS('3DA by Week'!$B$2:F$2,'3DA by Week'!$B6:F6,">=0"))-1)) | H6: =IF(NOT(ISNUMBER('3DA by Week'!H6)),"",IF(_xlfn.MAXIFS('3DA by Week'!$B$2:G$2,'3DA by Week'!$B6:G6,">=0")=0,"",'3DA by Week'!H6/INDEX('3DA by Week'!$B6:$K6,_xlfn.MAXIFS('3DA by Week'!$B$2:G$2,'3DA by Week'!$B6:G6,">=0"))-1)) | I6: =IF(NOT(ISNUMBER('3DA by Week'!I6)),"",IF(_xlfn.MAXIFS('3DA by Week'!$B$2:H$2,'3DA by Week'!$B6:H6,">=0")=0,"",'3DA by Week'!I6/INDEX('3DA by Week'!$B6:$K6,_xlfn.MAXIFS('3DA by Week'!$B$2:H$2,'3DA by Week'!$B6:H6,">=0"))-1)) | J6: =IF(NOT(ISNUMBER('3DA by Week'!J6)),"",IF(_xlfn.MAXIFS('3DA by Week'!$B$2:I$2,'3DA by Week'!$B6:I6,">=0")=0,"",'3DA by Week'!J6/INDEX('3DA by Week'!$B6:$K6,_xlfn.MAXIFS('3DA by Week'!$B$2:I$2,'3DA by Week'!$B6:I6,">=0"))-1)) | K6: =IF(NOT(ISNUMBER('3DA by Week'!K6)),"",IF(_xlfn.MAXIFS('3DA by Week'!$B$2:J$2,'3DA by Week'!$B6:J6,">=0")=0,"",'3DA by Week'!K6/INDEX('3DA by Week'!$B6:$K6,_xlfn.MAXIFS('3DA by Week'!$B$2:J$2,'3DA by Week'!$B6:J6,">=0"))-1))
A7: Bill Prelle | C7: =IF(NOT(ISNUMBER('3DA by Week'!C7)),"",IF(_xlfn.MAXIFS('3DA by Week'!$B$2:B$2,'3DA by Week'!$B7:B7,">=0")=0,"",'3DA by Week'!C7/INDEX('3DA by Week'!$B7:$K7,_xlfn.MAXIFS('3DA by Week'!$B$2:B$2,'3DA by Week'!$B7:B7,">=0"))-1)) | D7: =IF(NOT(ISNUMBER('3DA by Week'!D7)),"",IF(_xlfn.MAXIFS('3DA by Week'!$B$2:C$2,'3DA by Week'!$B7:C7,">=0")=0,"",'3DA by Week'!D7/INDEX('3DA by Week'!$B7:$K7,_xlfn.MAXIFS('3DA by Week'!$B$2:C$2,'3DA by Week'!$B7:C7,">=0"))-1)) | E7: =IF(NOT(ISNUMBER('3DA by Week'!E7)),"",IF(_xlfn.MAXIFS('3DA by Week'!$B$2:D$2,'3DA by Week'!$B7:D7,">=0")=0,"",'3DA by Week'!E7/INDEX('3DA by Week'!$B7:$K7,_xlfn.MAXIFS('3DA by Week'!$B$2:D$2,'3DA by Week'!$B7:D7,">=0"))-1)) | F7: =IF(NOT(ISNUMBER('3DA by Week'!F7)),"",IF(_xlfn.MAXIFS('3DA by Week'!$B$2:E$2,'3DA by Week'!$B7:E7,">=0")=0,"",'3DA by Week'!F7/INDEX('3DA by Week'!$B7:$K7,_xlfn.MAXIFS('3DA by Week'!$B$2:E$2,'3DA by Week'!$B7:E7,">=0"))-1)) | G7: =IF(NOT(ISNUMBER('3DA by Week'!G7)),"",IF(_xlfn.MAXIFS('3DA by Week'!$B$2:F$2,'3DA by Week'!$B7:F7,">=0")=0,"",'3DA by Week'!G7/INDEX('3DA by Week'!$B7:$K7,_xlfn.MAXIFS('3DA by Week'!$B$2:F$2,'3DA by Week'!$B7:F7,">=0"))-1)) | H7: =IF(NOT(ISNUMBER('3DA by Week'!H7)),"",IF(_xlfn.MAXIFS('3DA by Week'!$B$2:G$2,'3DA by Week'!$B7:G7,">=0")=0,"",'3DA by Week'!H7/INDEX('3DA by Week'!$B7:$K7,_xlfn.MAXIFS('3DA by Week'!$B$2:G$2,'3DA by Week'!$B7:G7,">=0"))-1)) | I7: =IF(NOT(ISNUMBER('3DA by Week'!I7)),"",IF(_xlfn.MAXIFS('3DA by Week'!$B$2:H$2,'3DA by Week'!$B7:H7,">=0")=0,"",'3DA by Week'!I7/INDEX('3DA by Week'!$B7:$K7,_xlfn.MAXIFS('3DA by Week'!$B$2:H$2,'3DA by Week'!$B7:H7,">=0"))-1)) | J7: =IF(NOT(ISNUMBER('3DA by Week'!J7)),"",IF(_xlfn.MAXIFS('3DA by Week'!$B$2:I$2,'3DA by Week'!$B7:I7,">=0")=0,"",'3DA by Week'!J7/INDEX('3DA by Week'!$B7:$K7,_xlfn.MAXIFS('3DA by Week'!$B$2:I$2,'3DA by Week'!$B7:I7,">=0"))-1)) | K7: =IF(NOT(ISNUMBER('3DA by Week'!K7)),"",IF(_xlfn.MAXIFS('3DA by Week'!$B$2:J$2,'3DA by Week'!$B7:J7,">=0")=0,"",'3DA by Week'!K7/INDEX('3DA by Week'!$B7:$K7,_xlfn.MAXIFS('3DA by Week'!$B$2:J$2,'3DA by Week'!$B7:J7,">=0"))-1))
A8: Keith McCarthy | C8: =IF(NOT(ISNUMBER('3DA by Week'!C8)),"",IF(_xlfn.MAXIFS('3DA by Week'!$B$2:B$2,'3DA by Week'!$B8:B8,">=0")=0,"",'3DA by Week'!C8/INDEX('3DA by Week'!$B8:$K8,_xlfn.MAXIFS('3DA by Week'!$B$2:B$2,'3DA by Week'!$B8:B8,">=0"))-1)) | D8: =IF(NOT(ISNUMBER('3DA by Week'!D8)),"",IF(_xlfn.MAXIFS('3DA by Week'!$B$2:C$2,'3DA by Week'!$B8:C8,">=0")=0,"",'3DA by Week'!D8/INDEX('3DA by Week'!$B8:$K8,_xlfn.MAXIFS('3DA by Week'!$B$2:C$2,'3DA by Week'!$B8:C8,">=0"))-1)) | E8: =IF(NOT(ISNUMBER('3DA by Week'!E8)),"",IF(_xlfn.MAXIFS('3DA by Week'!$B$2:D$2,'3DA by Week'!$B8:D8,">=0")=0,"",'3DA by Week'!E8/INDEX('3DA by Week'!$B8:$K8,_xlfn.MAXIFS('3DA by Week'!$B$2:D$2,'3DA by Week'!$B8:D8,">=0"))-1)) | F8: =IF(NOT(ISNUMBER('3DA by Week'!F8)),"",IF(_xlfn.MAXIFS('3DA by Week'!$B$2:E$2,'3DA by Week'!$B8:E8,">=0")=0,"",'3DA by Week'!F8/INDEX('3DA by Week'!$B8:$K8,_xlfn.MAXIFS('3DA by Week'!$B$2:E$2,'3DA by Week'!$B8:E8,">=0"))-1)) | G8: =IF(NOT(ISNUMBER('3DA by Week'!G8)),"",IF(_xlfn.MAXIFS('3DA by Week'!$B$2:F$2,'3DA by Week'!$B8:F8,">=0")=0,"",'3DA by Week'!G8/INDEX('3DA by Week'!$B8:$K8,_xlfn.MAXIFS('3DA by Week'!$B$2:F$2,'3DA by Week'!$B8:F8,">=0"))-1)) | H8: =IF(NOT(ISNUMBER('3DA by Week'!H8)),"",IF(_xlfn.MAXIFS('3DA by Week'!$B$2:G$2,'3DA by Week'!$B8:G8,">=0")=0,"",'3DA by Week'!H8/INDEX('3DA by Week'!$B8:$K8,_xlfn.MAXIFS('3DA by Week'!$B$2:G$2,'3DA by Week'!$B8:G8,">=0"))-1)) | I8: =IF(NOT(ISNUMBER('3DA by Week'!I8)),"",IF(_xlfn.MAXIFS('3DA by Week'!$B$2:H$2,'3DA by Week'!$B8:H8,">=0")=0,"",'3DA by Week'!I8/INDEX('3DA by Week'!$B8:$K8,_xlfn.MAXIFS('3DA by Week'!$B$2:H$2,'3DA by Week'!$B8:H8,">=0"))-1)) | J8: =IF(NOT(ISNUMBER('3DA by Week'!J8)),"",IF(_xlfn.MAXIFS('3DA by Week'!$B$2:I$2,'3DA by Week'!$B8:I8,">=0")=0,"",'3DA by Week'!J8/INDEX('3DA by Week'!$B8:$K8,_xlfn.MAXIFS('3DA by Week'!$B$2:I$2,'3DA by Week'!$B8:I8,">=0"))-1)) | K8: =IF(NOT(ISNUMBER('3DA by Week'!K8)),"",IF(_xlfn.MAXIFS('3DA by Week'!$B$2:J$2,'3DA by Week'!$B8:J8,">=0")=0,"",'3DA by Week'!K8/INDEX('3DA by Week'!$B8:$K8,_xlfn.MAXIFS('3DA by Week'!$B$2:J$2,'3DA by Week'!$B8:J8,">=0"))-1))
A9: Tom Davis | C9: =IF(NOT(ISNUMBER('3DA by Week'!C9)),"",IF(_xlfn.MAXIFS('3DA by Week'!$B$2:B$2,'3DA by Week'!$B9:B9,">=0")=0,"",'3DA by Week'!C9/INDEX('3DA by Week'!$B9:$K9,_xlfn.MAXIFS('3DA by Week'!$B$2:B$2,'3DA by Week'!$B9:B9,">=0"))-1)) | D9: =IF(NOT(ISNUMBER('3DA by Week'!D9)),"",IF(_xlfn.MAXIFS('3DA by Week'!$B$2:C$2,'3DA by Week'!$B9:C9,">=0")=0,"",'3DA by Week'!D9/INDEX('3DA by Week'!$B9:$K9,_xlfn.MAXIFS('3DA by Week'!$B$2:C$2,'3DA by Week'!$B9:C9,">=0"))-1)) | E9: =IF(NOT(ISNUMBER('3DA by Week'!E9)),"",IF(_xlfn.MAXIFS('3DA by Week'!$B$2:D$2,'3DA by Week'!$B9:D9,">=0")=0,"",'3DA by Week'!E9/INDEX('3DA by Week'!$B9:$K9,_xlfn.MAXIFS('3DA by Week'!$B$2:D$2,'3DA by Week'!$B9:D9,">=0"))-1)) | F9: =IF(NOT(ISNUMBER('3DA by Week'!F9)),"",IF(_xlfn.MAXIFS('3DA by Week'!$B$2:E$2,'3DA by Week'!$B9:E9,">=0")=0,"",'3DA by Week'!F9/INDEX('3DA by Week'!$B9:$K9,_xlfn.MAXIFS('3DA by Week'!$B$2:E$2,'3DA by Week'!$B9:E9,">=0"))-1)) | G9: =IF(NOT(ISNUMBER('3DA by Week'!G9)),"",IF(_xlfn.MAXIFS('3DA by Week'!$B$2:F$2,'3DA by Week'!$B9:F9,">=0")=0,"",'3DA by Week'!G9/INDEX('3DA by Week'!$B9:$K9,_xlfn.MAXIFS('3DA by Week'!$B$2:F$2,'3DA by Week'!$B9:F9,">=0"))-1)) | H9: =IF(NOT(ISNUMBER('3DA by Week'!H9)),"",IF(_xlfn.MAXIFS('3DA by Week'!$B$2:G$2,'3DA by Week'!$B9:G9,">=0")=0,"",'3DA by Week'!H9/INDEX('3DA by Week'!$B9:$K9,_xlfn.MAXIFS('3DA by Week'!$B$2:G$2,'3DA by Week'!$B9:G9,">=0"))-1)) | I9: =IF(NOT(ISNUMBER('3DA by Week'!I9)),"",IF(_xlfn.MAXIFS('3DA by Week'!$B$2:H$2,'3DA by Week'!$B9:H9,">=0")=0,"",'3DA by Week'!I9/INDEX('3DA by Week'!$B9:$K9,_xlfn.MAXIFS('3DA by Week'!$B$2:H$2,'3DA by Week'!$B9:H9,">=0"))-1)) | J9: =IF(NOT(ISNUMBER('3DA by Week'!J9)),"",IF(_xlfn.MAXIFS('3DA by Week'!$B$2:I$2,'3DA by Week'!$B9:I9,">=0")=0,"",'3DA by Week'!J9/INDEX('3DA by Week'!$B9:$K9,_xlfn.MAXIFS('3DA by Week'!$B$2:I$2,'3DA by Week'!$B9:I9,">=0"))-1)) | K9: =IF(NOT(ISNUMBER('3DA by Week'!K9)),"",IF(_xlfn.MAXIFS('3DA by Week'!$B$2:J$2,'3DA by Week'!$B9:J9,">=0")=0,"",'3DA by Week'!K9/INDEX('3DA by Week'!$B9:$K9,_xlfn.MAXIFS('3DA by Week'!$B$2:J$2,'3DA by Week'!$B9:J9,">=0"))-1))
A10: John Klemick | C10: =IF(NOT(ISNUMBER('3DA by Week'!C10)),"",IF(_xlfn.MAXIFS('3DA by Week'!$B$2:B$2,'3DA by Week'!$B10:B10,">=0")=0,"",'3DA by Week'!C10/INDEX('3DA by Week'!$B10:$K10,_xlfn.MAXIFS('3DA by Week'!$B$2:B$2,'3DA by Week'!$B10:B10,">=0"))-1)) | D10: =IF(NOT(ISNUMBER('3DA by Week'!D10)),"",IF(_xlfn.MAXIFS('3DA by Week'!$B$2:C$2,'3DA by Week'!$B10:C10,">=0")=0,"",'3DA by Week'!D10/INDEX('3DA by Week'!$B10:$K10,_xlfn.MAXIFS('3DA by Week'!$B$2:C$2,'3DA by Week'!$B10:C10,">=0"))-1)) | E10: =IF(NOT(ISNUMBER('3DA by Week'!E10)),"",IF(_xlfn.MAXIFS('3DA by Week'!$B$2:D$2,'3DA by Week'!$B10:D10,">=0")=0,"",'3DA by Week'!E10/INDEX('3DA by Week'!$B10:$K10,_xlfn.MAXIFS('3DA by Week'!$B$2:D$2,'3DA by Week'!$B10:D10,">=0"))-1)) | F10: =IF(NOT(ISNUMBER('3DA by Week'!F10)),"",IF(_xlfn.MAXIFS('3DA by Week'!$B$2:E$2,'3DA by Week'!$B10:E10,">=0")=0,"",'3DA by Week'!F10/INDEX('3DA by Week'!$B10:$K10,_xlfn.MAXIFS('3DA by Week'!$B$2:E$2,'3DA by Week'!$B10:E10,">=0"))-1)) | G10: =IF(NOT(ISNUMBER('3DA by Week'!G10)),"",IF(_xlfn.MAXIFS('3DA by Week'!$B$2:F$2,'3DA by Week'!$B10:F10,">=0")=0,"",'3DA by Week'!G10/INDEX('3DA by Week'!$B10:$K10,_xlfn.MAXIFS('3DA by Week'!$B$2:F$2,'3DA by Week'!$B10:F10,">=0"))-1)) | H10: =IF(NOT(ISNUMBER('3DA by Week'!H10)),"",IF(_xlfn.MAXIFS('3DA by Week'!$B$2:G$2,'3DA by Week'!$B10:G10,">=0")=0,"",'3DA by Week'!H10/INDEX('3DA by Week'!$B10:$K10,_xlfn.MAXIFS('3DA by Week'!$B$2:G$2,'3DA by Week'!$B10:G10,">=0"))-1)) | I10: =IF(NOT(ISNUMBER('3DA by Week'!I10)),"",IF(_xlfn.MAXIFS('3DA by Week'!$B$2:H$2,'3DA by Week'!$B10:H10,">=0")=0,"",'3DA by Week'!I10/INDEX('3DA by Week'!$B10:$K10,_xlfn.MAXIFS('3DA by Week'!$B$2:H$2,'3DA by Week'!$B10:H10,">=0"))-1)) | J10: =IF(NOT(ISNUMBER('3DA by Week'!J10)),"",IF(_xlfn.MAXIFS('3DA by Week'!$B$2:I$2,'3DA by Week'!$B10:I10,">=0")=0,"",'3DA by Week'!J10/INDEX('3DA by Week'!$B10:$K10,_xlfn.MAXIFS('3DA by Week'!$B$2:I$2,'3DA by Week'!$B10:I10,">=0"))-1)) | K10: =IF(NOT(ISNUMBER('3DA by Week'!K10)),"",IF(_xlfn.MAXIFS('3DA by Week'!$B$2:J$2,'3DA by Week'!$B10:J10,">=0")=0,"",'3DA by Week'!K10/INDEX('3DA by Week'!$B10:$K10,_xlfn.MAXIFS('3DA by Week'!$B$2:J$2,'3DA by Week'!$B10:J10,">=0"))-1))
